[2024-01-01T14:41:52.815+0530] {taskinstance.py:1159} INFO - Dependencies all met for dep_context=non-requeueable deps ti=<TaskInstance: summa1.manual_trigger scheduled__2023-12-30T00:00:00+00:00 [queued]>
[2024-01-01T14:41:52.820+0530] {taskinstance.py:1159} INFO - Dependencies all met for dep_context=requeueable deps ti=<TaskInstance: summa1.manual_trigger scheduled__2023-12-30T00:00:00+00:00 [queued]>
[2024-01-01T14:41:52.820+0530] {taskinstance.py:1361} INFO - Starting attempt 1 of 2
[2024-01-01T14:41:52.830+0530] {taskinstance.py:1382} INFO - Executing <Task(TriggerDagRunOperator): manual_trigger> on 2023-12-30 00:00:00+00:00
[2024-01-01T14:41:52.833+0530] {standard_task_runner.py:57} INFO - Started process 23027 to run task
[2024-01-01T14:41:52.835+0530] {standard_task_runner.py:84} INFO - Running: ['airflow', 'tasks', 'run', 'summa1', 'manual_trigger', 'scheduled__2023-12-30T00:00:00+00:00', '--job-id', '508', '--raw', '--subdir', 'DAGS_FOLDER/summa.py', '--cfg-path', '/tmp/tmp166_qfxr']
[2024-01-01T14:41:52.836+0530] {standard_task_runner.py:85} INFO - Job 508: Subtask manual_trigger
[2024-01-01T14:41:52.858+0530] {task_command.py:416} INFO - Running <TaskInstance: summa1.manual_trigger scheduled__2023-12-30T00:00:00+00:00 [running]> on host Iris
[2024-01-01T14:41:52.901+0530] {taskinstance.py:1662} INFO - Exporting env vars: AIRFLOW_CTX_DAG_OWNER='your_username' AIRFLOW_CTX_DAG_ID='summa1' AIRFLOW_CTX_TASK_ID='manual_trigger' AIRFLOW_CTX_EXECUTION_DATE='2023-12-30T00:00:00+00:00' AIRFLOW_CTX_TRY_NUMBER='1' AIRFLOW_CTX_DAG_RUN_ID='scheduled__2023-12-30T00:00:00+00:00'
[2024-01-01T14:41:52.998+0530] {taskinstance.py:1937} ERROR - Task failed with exception
Traceback (most recent call last):
  File "/home/rajabala/Desktop/projects/Airflow/airflow_env/lib/python3.9/site-packages/airflow/operators/trigger_dagrun.py", line 186, in execute
    raise e
  File "/home/rajabala/Desktop/projects/Airflow/airflow_env/lib/python3.9/site-packages/airflow/operators/trigger_dagrun.py", line 163, in execute
    dag_run = trigger_dag(
  File "/home/rajabala/Desktop/projects/Airflow/airflow_env/lib/python3.9/site-packages/airflow/api/common/trigger_dag.py", line 122, in trigger_dag
    triggers = _trigger_dag(
  File "/home/rajabala/Desktop/projects/Airflow/airflow_env/lib/python3.9/site-packages/airflow/api/common/trigger_dag.py", line 78, in _trigger_dag
    raise DagRunAlreadyExists(dag_run=dag_run, execution_date=execution_date, run_id=run_id)
airflow.exceptions.DagRunAlreadyExists: A DAG Run already exists for DAG summa1 at 2024-01-06 00:00:00+00:00 with run id manual__2024-01-06T00:00:00+00:00
[2024-01-01T14:41:53.000+0530] {taskinstance.py:1400} INFO - Marking task as UP_FOR_RETRY. dag_id=summa1, task_id=manual_trigger, execution_date=20231230T000000, start_date=20240101T091152, end_date=20240101T091152
[2024-01-01T14:41:53.010+0530] {standard_task_runner.py:104} ERROR - Failed to execute job 508 for task manual_trigger (A DAG Run already exists for DAG summa1 at 2024-01-06 00:00:00+00:00 with run id manual__2024-01-06T00:00:00+00:00; 23027)
[2024-01-01T14:41:53.048+0530] {local_task_job_runner.py:228} INFO - Task exited with return code 1
[2024-01-01T14:41:53.067+0530] {taskinstance.py:2778} INFO - 0 downstream tasks scheduled from follow-on schedule check
[2024-01-01T14:50:19.470+0530] {taskinstance.py:1159} INFO - Dependencies all met for dep_context=non-requeueable deps ti=<TaskInstance: summa1.manual_trigger scheduled__2023-12-30T00:00:00+00:00 [queued]>
[2024-01-01T14:50:19.475+0530] {taskinstance.py:1159} INFO - Dependencies all met for dep_context=requeueable deps ti=<TaskInstance: summa1.manual_trigger scheduled__2023-12-30T00:00:00+00:00 [queued]>
[2024-01-01T14:50:19.476+0530] {taskinstance.py:1361} INFO - Starting attempt 1 of 2
[2024-01-01T14:50:19.490+0530] {taskinstance.py:1382} INFO - Executing <Task(TriggerDagRunOperator): manual_trigger> on 2023-12-30 00:00:00+00:00
[2024-01-01T14:50:19.492+0530] {standard_task_runner.py:57} INFO - Started process 28284 to run task
[2024-01-01T14:50:19.495+0530] {standard_task_runner.py:84} INFO - Running: ['airflow', 'tasks', 'run', 'summa1', 'manual_trigger', 'scheduled__2023-12-30T00:00:00+00:00', '--job-id', '510', '--raw', '--subdir', 'DAGS_FOLDER/summa.py', '--cfg-path', '/tmp/tmpxluymoja']
[2024-01-01T14:50:19.495+0530] {standard_task_runner.py:85} INFO - Job 510: Subtask manual_trigger
[2024-01-01T14:50:19.525+0530] {task_command.py:416} INFO - Running <TaskInstance: summa1.manual_trigger scheduled__2023-12-30T00:00:00+00:00 [running]> on host Iris
[2024-01-01T14:50:19.580+0530] {taskinstance.py:1662} INFO - Exporting env vars: AIRFLOW_CTX_DAG_OWNER='your_username' AIRFLOW_CTX_DAG_ID='summa1' AIRFLOW_CTX_TASK_ID='manual_trigger' AIRFLOW_CTX_EXECUTION_DATE='2023-12-30T00:00:00+00:00' AIRFLOW_CTX_TRY_NUMBER='1' AIRFLOW_CTX_DAG_RUN_ID='scheduled__2023-12-30T00:00:00+00:00'
[2024-01-01T14:50:19.704+0530] {taskinstance.py:1937} ERROR - Task failed with exception
Traceback (most recent call last):
  File "/home/rajabala/Desktop/projects/Airflow/airflow_env/lib/python3.9/site-packages/airflow/operators/trigger_dagrun.py", line 186, in execute
    raise e
  File "/home/rajabala/Desktop/projects/Airflow/airflow_env/lib/python3.9/site-packages/airflow/operators/trigger_dagrun.py", line 163, in execute
    dag_run = trigger_dag(
  File "/home/rajabala/Desktop/projects/Airflow/airflow_env/lib/python3.9/site-packages/airflow/api/common/trigger_dag.py", line 122, in trigger_dag
    triggers = _trigger_dag(
  File "/home/rajabala/Desktop/projects/Airflow/airflow_env/lib/python3.9/site-packages/airflow/api/common/trigger_dag.py", line 78, in _trigger_dag
    raise DagRunAlreadyExists(dag_run=dag_run, execution_date=execution_date, run_id=run_id)
airflow.exceptions.DagRunAlreadyExists: A DAG Run already exists for DAG summa1 at 2023-12-31 00:00:00+00:00 with run id manual__2023-12-31T00:00:00+00:00
[2024-01-01T14:50:19.709+0530] {taskinstance.py:1400} INFO - Marking task as UP_FOR_RETRY. dag_id=summa1, task_id=manual_trigger, execution_date=20231230T000000, start_date=20240101T092019, end_date=20240101T092019
[2024-01-01T14:50:19.731+0530] {standard_task_runner.py:104} ERROR - Failed to execute job 510 for task manual_trigger (A DAG Run already exists for DAG summa1 at 2023-12-31 00:00:00+00:00 with run id manual__2023-12-31T00:00:00+00:00; 28284)
[2024-01-01T14:50:19.747+0530] {local_task_job_runner.py:228} INFO - Task exited with return code 1
[2024-01-01T14:50:19.773+0530] {taskinstance.py:2778} INFO - 0 downstream tasks scheduled from follow-on schedule check
