[2023-12-09T19:31:53.004+0530] {taskinstance.py:1159} INFO - Dependencies all met for dep_context=non-requeueable deps ti=<TaskInstance: Cricbuzz_ETL.load manual__2023-12-09T14:01:20.972037+00:00 [queued]>
[2023-12-09T19:31:53.011+0530] {taskinstance.py:1159} INFO - Dependencies all met for dep_context=requeueable deps ti=<TaskInstance: Cricbuzz_ETL.load manual__2023-12-09T14:01:20.972037+00:00 [queued]>
[2023-12-09T19:31:53.012+0530] {taskinstance.py:1361} INFO - Starting attempt 1 of 1
[2023-12-09T19:31:53.024+0530] {taskinstance.py:1382} INFO - Executing <Task(PythonOperator): load> on 2023-12-09 14:01:20.972037+00:00
[2023-12-09T19:31:53.028+0530] {standard_task_runner.py:57} INFO - Started process 53464 to run task
[2023-12-09T19:31:53.032+0530] {standard_task_runner.py:84} INFO - Running: ['airflow', 'tasks', 'run', 'Cricbuzz_ETL', 'load', 'manual__2023-12-09T14:01:20.972037+00:00', '--job-id', '220', '--raw', '--subdir', 'DAGS_FOLDER/Crickbuzz_dag.py', '--cfg-path', '/tmp/tmp6c_dfhh4']
[2023-12-09T19:31:53.033+0530] {standard_task_runner.py:85} INFO - Job 220: Subtask load
[2023-12-09T19:31:53.060+0530] {task_command.py:416} INFO - Running <TaskInstance: Cricbuzz_ETL.load manual__2023-12-09T14:01:20.972037+00:00 [running]> on host Iris
[2023-12-09T19:31:53.124+0530] {taskinstance.py:1662} INFO - Exporting env vars: AIRFLOW_CTX_DAG_OWNER='airflow' AIRFLOW_CTX_DAG_ID='Cricbuzz_ETL' AIRFLOW_CTX_TASK_ID='load' AIRFLOW_CTX_EXECUTION_DATE='2023-12-09T14:01:20.972037+00:00' AIRFLOW_CTX_TRY_NUMBER='1' AIRFLOW_CTX_DAG_RUN_ID='manual__2023-12-09T14:01:20.972037+00:00'
[2023-12-09T19:31:53.193+0530] {taskinstance.py:1937} ERROR - Task failed with exception
Traceback (most recent call last):
  File "/home/rajabala/Desktop/projects/Airflow/airflow_env/lib/python3.9/site-packages/sqlalchemy/engine/base.py", line 1910, in _execute_context
    self.dialect.do_execute(
  File "/home/rajabala/Desktop/projects/Airflow/airflow_env/lib/python3.9/site-packages/sqlalchemy/engine/default.py", line 736, in do_execute
    cursor.execute(statement, parameters)
psycopg2.errors.UniqueViolation: duplicate key value violates unique constraint "match_data_pkey"
DETAIL:  Key (match_id)=(10082023) already exists.


The above exception was the direct cause of the following exception:

Traceback (most recent call last):
  File "/home/rajabala/Desktop/projects/Airflow/airflow_env/lib/python3.9/site-packages/airflow/operators/python.py", line 192, in execute
    return_value = self.execute_callable()
  File "/home/rajabala/Desktop/projects/Airflow/airflow_env/lib/python3.9/site-packages/airflow/operators/python.py", line 209, in execute_callable
    return self.python_callable(*self.op_args, **self.op_kwargs)
  File "/home/rajabala/Desktop/projects/Airflow/dags/Cricbuzz_files/Load.py", line 36, in load_to_db
    match_data.to_sql(name='match_data',con=conn,index=False, if_exists='append')
  File "/home/rajabala/Desktop/projects/Airflow/airflow_env/lib/python3.9/site-packages/pandas/core/generic.py", line 2951, in to_sql
    return sql.to_sql(
  File "/home/rajabala/Desktop/projects/Airflow/airflow_env/lib/python3.9/site-packages/pandas/io/sql.py", line 697, in to_sql
    return pandas_sql.to_sql(
  File "/home/rajabala/Desktop/projects/Airflow/airflow_env/lib/python3.9/site-packages/pandas/io/sql.py", line 1739, in to_sql
    total_inserted = sql_engine.insert_records(
  File "/home/rajabala/Desktop/projects/Airflow/airflow_env/lib/python3.9/site-packages/pandas/io/sql.py", line 1332, in insert_records
    raise err
  File "/home/rajabala/Desktop/projects/Airflow/airflow_env/lib/python3.9/site-packages/pandas/io/sql.py", line 1322, in insert_records
    return table.insert(chunksize=chunksize, method=method)
  File "/home/rajabala/Desktop/projects/Airflow/airflow_env/lib/python3.9/site-packages/pandas/io/sql.py", line 950, in insert
    num_inserted = exec_insert(conn, keys, chunk_iter)
  File "/home/rajabala/Desktop/projects/Airflow/airflow_env/lib/python3.9/site-packages/pandas/io/sql.py", line 857, in _execute_insert
    result = conn.execute(self.table.insert(), data)
  File "/home/rajabala/Desktop/projects/Airflow/airflow_env/lib/python3.9/site-packages/sqlalchemy/engine/base.py", line 1385, in execute
    return meth(self, multiparams, params, _EMPTY_EXECUTION_OPTS)
  File "/home/rajabala/Desktop/projects/Airflow/airflow_env/lib/python3.9/site-packages/sqlalchemy/sql/elements.py", line 334, in _execute_on_connection
    return connection._execute_clauseelement(
  File "/home/rajabala/Desktop/projects/Airflow/airflow_env/lib/python3.9/site-packages/sqlalchemy/engine/base.py", line 1577, in _execute_clauseelement
    ret = self._execute_context(
  File "/home/rajabala/Desktop/projects/Airflow/airflow_env/lib/python3.9/site-packages/sqlalchemy/engine/base.py", line 1953, in _execute_context
    self._handle_dbapi_exception(
  File "/home/rajabala/Desktop/projects/Airflow/airflow_env/lib/python3.9/site-packages/sqlalchemy/engine/base.py", line 2134, in _handle_dbapi_exception
    util.raise_(
  File "/home/rajabala/Desktop/projects/Airflow/airflow_env/lib/python3.9/site-packages/sqlalchemy/util/compat.py", line 211, in raise_
    raise exception
  File "/home/rajabala/Desktop/projects/Airflow/airflow_env/lib/python3.9/site-packages/sqlalchemy/engine/base.py", line 1910, in _execute_context
    self.dialect.do_execute(
  File "/home/rajabala/Desktop/projects/Airflow/airflow_env/lib/python3.9/site-packages/sqlalchemy/engine/default.py", line 736, in do_execute
    cursor.execute(statement, parameters)
sqlalchemy.exc.IntegrityError: (psycopg2.errors.UniqueViolation) duplicate key value violates unique constraint "match_data_pkey"
DETAIL:  Key (match_id)=(10082023) already exists.

[SQL: INSERT INTO match_data (match_id, match_no, date, series, season, venue, team_a, team_b, team_a_11, team_b_11, team_a_subs, team_b_subs, toss, toss_winner, toss_choosen, winner, player_of_the_match) VALUES (%(match_id)s, %(match_no)s, %(date)s, %(series)s, %(season)s, %(venue)s, %(team_a)s, %(team_b)s, %(team_a_11)s, %(team_b_11)s, %(team_a_subs)s, %(team_b_subs)s, %(toss)s, %(toss_winner)s, %(toss_choosen)s, %(winner)s, %(player_of_the_match)s)]
[parameters: {'match_id': '10082023', 'match_no': '5th', 'date': 'Oct 08,2023', 'series': 'ICC Cricket World Cup 2023', 'season': 2023, 'venue': 'MA Chidambaram Stadium,Chennai', 'team_a': 'India', 'team_b': 'Australia', 'team_a_11': 'India (Playing XI): Rohit Sharma(c), Ishan Kishan, Virat Kohli, Shreyas Iyer, KL Rahul(w), Hardik Pandya, Ravindra Jadeja, Ravichandran Ashwin, Kuldeep Yadav, Jasprit Bumrah, Mohammed Siraj', 'team_b_11': 'Australia (Playing XI): David Warner, Mitchell Marsh, Steven Smith, Marnus Labuschagne, Glenn Maxwell, Alex Carey(w), Cameron Green, Pat Cummins(c), Mitchell Starc, Adam Zampa, Josh Hazlewood', 'team_a_subs': None, 'team_b_subs': None, 'toss': 'Australia have won the toss and have opted to bat', 'toss_winner': 'AUS', 'toss_choosen': 'bat', 'winner': 'India won by 6 wkts', 'player_of_the_match': 'KL Rahul'}]
(Background on this error at: https://sqlalche.me/e/14/gkpj)
[2023-12-09T19:31:53.200+0530] {taskinstance.py:1400} INFO - Marking task as FAILED. dag_id=Cricbuzz_ETL, task_id=load, execution_date=20231209T140120, start_date=20231209T140153, end_date=20231209T140153
[2023-12-09T19:31:53.212+0530] {standard_task_runner.py:104} ERROR - Failed to execute job 220 for task load ((psycopg2.errors.UniqueViolation) duplicate key value violates unique constraint "match_data_pkey"
DETAIL:  Key (match_id)=(10082023) already exists.

[SQL: INSERT INTO match_data (match_id, match_no, date, series, season, venue, team_a, team_b, team_a_11, team_b_11, team_a_subs, team_b_subs, toss, toss_winner, toss_choosen, winner, player_of_the_match) VALUES (%(match_id)s, %(match_no)s, %(date)s, %(series)s, %(season)s, %(venue)s, %(team_a)s, %(team_b)s, %(team_a_11)s, %(team_b_11)s, %(team_a_subs)s, %(team_b_subs)s, %(toss)s, %(toss_winner)s, %(toss_choosen)s, %(winner)s, %(player_of_the_match)s)]
[parameters: {'match_id': '10082023', 'match_no': '5th', 'date': 'Oct 08,2023', 'series': 'ICC Cricket World Cup 2023', 'season': 2023, 'venue': 'MA Chidambaram Stadium,Chennai', 'team_a': 'India', 'team_b': 'Australia', 'team_a_11': 'India (Playing XI): Rohit Sharma(c), Ishan Kishan, Virat Kohli, Shreyas Iyer, KL Rahul(w), Hardik Pandya, Ravindra Jadeja, Ravichandran Ashwin, Kuldeep Yadav, Jasprit Bumrah, Mohammed Siraj', 'team_b_11': 'Australia (Playing XI): David Warner, Mitchell Marsh, Steven Smith, Marnus Labuschagne, Glenn Maxwell, Alex Carey(w), Cameron Green, Pat Cummins(c), Mitchell Starc, Adam Zampa, Josh Hazlewood', 'team_a_subs': None, 'team_b_subs': None, 'toss': 'Australia have won the toss and have opted to bat', 'toss_winner': 'AUS', 'toss_choosen': 'bat', 'winner': 'India won by 6 wkts', 'player_of_the_match': 'KL Rahul'}]
(Background on this error at: https://sqlalche.me/e/14/gkpj); 53464)
[2023-12-09T19:31:53.244+0530] {local_task_job_runner.py:228} INFO - Task exited with return code 1
[2023-12-09T19:31:53.256+0530] {taskinstance.py:2778} INFO - 0 downstream tasks scheduled from follow-on schedule check
