[2024-01-02T17:32:26.696+0530] {taskinstance.py:1159} INFO - Dependencies all met for dep_context=non-requeueable deps ti=<TaskInstance: Cricbuzz_ETL.load manual__2024-01-02T12:01:57.278387+00:00 [queued]>
[2024-01-02T17:32:26.701+0530] {taskinstance.py:1159} INFO - Dependencies all met for dep_context=requeueable deps ti=<TaskInstance: Cricbuzz_ETL.load manual__2024-01-02T12:01:57.278387+00:00 [queued]>
[2024-01-02T17:32:26.701+0530] {taskinstance.py:1361} INFO - Starting attempt 1 of 1
[2024-01-02T17:32:26.712+0530] {taskinstance.py:1382} INFO - Executing <Task(PythonOperator): load> on 2024-01-02 12:01:57.278387+00:00
[2024-01-02T17:32:26.714+0530] {standard_task_runner.py:57} INFO - Started process 16812 to run task
[2024-01-02T17:32:26.716+0530] {standard_task_runner.py:84} INFO - Running: ['airflow', 'tasks', 'run', 'Cricbuzz_ETL', 'load', 'manual__2024-01-02T12:01:57.278387+00:00', '--job-id', '566', '--raw', '--subdir', 'DAGS_FOLDER/Crickbuzz_dag.py', '--cfg-path', '/tmp/tmpvas0s163']
[2024-01-02T17:32:26.717+0530] {standard_task_runner.py:85} INFO - Job 566: Subtask load
[2024-01-02T17:32:26.741+0530] {task_command.py:416} INFO - Running <TaskInstance: Cricbuzz_ETL.load manual__2024-01-02T12:01:57.278387+00:00 [running]> on host Iris
[2024-01-02T17:32:26.792+0530] {taskinstance.py:1662} INFO - Exporting env vars: AIRFLOW_CTX_DAG_OWNER='airflow' AIRFLOW_CTX_DAG_ID='Cricbuzz_ETL' AIRFLOW_CTX_TASK_ID='load' AIRFLOW_CTX_EXECUTION_DATE='2024-01-02T12:01:57.278387+00:00' AIRFLOW_CTX_TRY_NUMBER='1' AIRFLOW_CTX_DAG_RUN_ID='manual__2024-01-02T12:01:57.278387+00:00'
[2024-01-02T17:32:26.793+0530] {taskinstance.py:1937} ERROR - Task failed with exception
Traceback (most recent call last):
  File "/home/rajabala/Desktop/projects/Airflow/airflow_env/lib/python3.9/site-packages/airflow/operators/python.py", line 192, in execute
    return_value = self.execute_callable()
  File "/home/rajabala/Desktop/projects/Airflow/airflow_env/lib/python3.9/site-packages/airflow/operators/python.py", line 209, in execute_callable
    return self.python_callable(*self.op_args, **self.op_kwargs)
TypeError: load_to_db() takes 1 positional argument but 2 were given
[2024-01-02T17:32:26.797+0530] {taskinstance.py:1400} INFO - Marking task as FAILED. dag_id=Cricbuzz_ETL, task_id=load, execution_date=20240102T120157, start_date=20240102T120226, end_date=20240102T120226
[2024-01-02T17:32:26.807+0530] {standard_task_runner.py:104} ERROR - Failed to execute job 566 for task load (load_to_db() takes 1 positional argument but 2 were given; 16812)
[2024-01-02T17:32:26.849+0530] {local_task_job_runner.py:228} INFO - Task exited with return code 1
[2024-01-02T17:32:26.865+0530] {taskinstance.py:2778} INFO - 0 downstream tasks scheduled from follow-on schedule check
