[2023-12-31T21:06:35.072+0530] {taskinstance.py:1159} INFO - Dependencies all met for dep_context=non-requeueable deps ti=<TaskInstance: Cricbuzz_ETL2.load scheduled__2023-12-28T00:00:00+00:00 [queued]>
[2023-12-31T21:06:35.081+0530] {taskinstance.py:1159} INFO - Dependencies all met for dep_context=requeueable deps ti=<TaskInstance: Cricbuzz_ETL2.load scheduled__2023-12-28T00:00:00+00:00 [queued]>
[2023-12-31T21:06:35.081+0530] {taskinstance.py:1361} INFO - Starting attempt 1 of 1
[2023-12-31T21:06:35.100+0530] {taskinstance.py:1382} INFO - Executing <Task(PythonOperator): load> on 2023-12-28 00:00:00+00:00
[2023-12-31T21:06:35.103+0530] {standard_task_runner.py:57} INFO - Started process 19605 to run task
[2023-12-31T21:06:35.106+0530] {standard_task_runner.py:84} INFO - Running: ['airflow', 'tasks', 'run', 'Cricbuzz_ETL2', 'load', 'scheduled__2023-12-28T00:00:00+00:00', '--job-id', '440', '--raw', '--subdir', 'DAGS_FOLDER/summa.py', '--cfg-path', '/tmp/tmpwzbbvllc']
[2023-12-31T21:06:35.107+0530] {standard_task_runner.py:85} INFO - Job 440: Subtask load
[2023-12-31T21:06:35.144+0530] {task_command.py:416} INFO - Running <TaskInstance: Cricbuzz_ETL2.load scheduled__2023-12-28T00:00:00+00:00 [running]> on host Iris
[2023-12-31T21:06:35.188+0530] {taskinstance.py:1662} INFO - Exporting env vars: AIRFLOW_CTX_DAG_OWNER='airflow' AIRFLOW_CTX_DAG_ID='Cricbuzz_ETL2' AIRFLOW_CTX_TASK_ID='load' AIRFLOW_CTX_EXECUTION_DATE='2023-12-28T00:00:00+00:00' AIRFLOW_CTX_TRY_NUMBER='1' AIRFLOW_CTX_DAG_RUN_ID='scheduled__2023-12-28T00:00:00+00:00'
[2023-12-31T21:06:35.189+0530] {taskinstance.py:1937} ERROR - Task failed with exception
Traceback (most recent call last):
  File "/home/rajabala/Desktop/projects/Airflow/airflow_env/lib/python3.9/site-packages/airflow/operators/python.py", line 192, in execute
    return_value = self.execute_callable()
  File "/home/rajabala/Desktop/projects/Airflow/airflow_env/lib/python3.9/site-packages/airflow/operators/python.py", line 209, in execute_callable
    return self.python_callable(*self.op_args, **self.op_kwargs)
TypeError: load_to_db() takes 1 positional argument but 2 were given
[2023-12-31T21:06:35.192+0530] {taskinstance.py:1400} INFO - Marking task as FAILED. dag_id=Cricbuzz_ETL2, task_id=load, execution_date=20231228T000000, start_date=20231231T153635, end_date=20231231T153635
[2023-12-31T21:06:35.203+0530] {standard_task_runner.py:104} ERROR - Failed to execute job 440 for task load (load_to_db() takes 1 positional argument but 2 were given; 19605)
[2023-12-31T21:06:35.238+0530] {local_task_job_runner.py:228} INFO - Task exited with return code 1
[2023-12-31T21:06:35.253+0530] {taskinstance.py:2778} INFO - 0 downstream tasks scheduled from follow-on schedule check
