[2024-01-04T10:15:52.071+0530] {taskinstance.py:1159} INFO - Dependencies all met for dep_context=non-requeueable deps ti=<TaskInstance: Cricbuzz_ETL.transfer_to_hdfs scheduled__2024-01-03T00:00:00+00:00 [queued]>
[2024-01-04T10:15:52.077+0530] {taskinstance.py:1159} INFO - Dependencies all met for dep_context=requeueable deps ti=<TaskInstance: Cricbuzz_ETL.transfer_to_hdfs scheduled__2024-01-03T00:00:00+00:00 [queued]>
[2024-01-04T10:15:52.078+0530] {taskinstance.py:1361} INFO - Starting attempt 1 of 2
[2024-01-04T10:15:52.090+0530] {taskinstance.py:1382} INFO - Executing <Task(PythonOperator): transfer_to_hdfs> on 2024-01-03 00:00:00+00:00
[2024-01-04T10:15:52.093+0530] {standard_task_runner.py:57} INFO - Started process 12241 to run task
[2024-01-04T10:15:52.095+0530] {standard_task_runner.py:84} INFO - Running: ['airflow', 'tasks', 'run', 'Cricbuzz_ETL', 'transfer_to_hdfs', 'scheduled__2024-01-03T00:00:00+00:00', '--job-id', '731', '--raw', '--subdir', 'DAGS_FOLDER/Crickbuzz_dag.py', '--cfg-path', '/tmp/tmpbbq2lnlu']
[2024-01-04T10:15:52.096+0530] {standard_task_runner.py:85} INFO - Job 731: Subtask transfer_to_hdfs
[2024-01-04T10:15:52.125+0530] {task_command.py:416} INFO - Running <TaskInstance: Cricbuzz_ETL.transfer_to_hdfs scheduled__2024-01-03T00:00:00+00:00 [running]> on host Iris
[2024-01-04T10:15:52.169+0530] {taskinstance.py:1662} INFO - Exporting env vars: AIRFLOW_CTX_DAG_OWNER='airflow' AIRFLOW_CTX_DAG_ID='Cricbuzz_ETL' AIRFLOW_CTX_TASK_ID='transfer_to_hdfs' AIRFLOW_CTX_EXECUTION_DATE='2024-01-03T00:00:00+00:00' AIRFLOW_CTX_TRY_NUMBER='1' AIRFLOW_CTX_DAG_RUN_ID='scheduled__2024-01-03T00:00:00+00:00'
[2024-01-04T10:15:52.170+0530] {taskinstance.py:1937} ERROR - Task failed with exception
Traceback (most recent call last):
  File "/home/rajabala/Desktop/projects/Airflow/airflow_env/lib/python3.9/site-packages/airflow/operators/python.py", line 192, in execute
    return_value = self.execute_callable()
  File "/home/rajabala/Desktop/projects/Airflow/airflow_env/lib/python3.9/site-packages/airflow/operators/python.py", line 209, in execute_callable
    return self.python_callable(*self.op_args, **self.op_kwargs)
  File "/home/rajabala/Desktop/projects/Airflow/dags/Crickbuzz_dag.py", line 168, in load_to_hadoop
    conn.create_conn()
AttributeError: 'WebHDFSHook' object has no attribute 'create_conn'
[2024-01-04T10:15:52.173+0530] {taskinstance.py:1400} INFO - Marking task as UP_FOR_RETRY. dag_id=Cricbuzz_ETL, task_id=transfer_to_hdfs, execution_date=20240103T000000, start_date=20240104T044552, end_date=20240104T044552
[2024-01-04T10:15:52.182+0530] {standard_task_runner.py:104} ERROR - Failed to execute job 731 for task transfer_to_hdfs ('WebHDFSHook' object has no attribute 'create_conn'; 12241)
[2024-01-04T10:15:52.187+0530] {local_task_job_runner.py:228} INFO - Task exited with return code 1
[2024-01-04T10:15:52.197+0530] {taskinstance.py:2778} INFO - 0 downstream tasks scheduled from follow-on schedule check
