[2023-12-31T21:08:00.247+0530] {taskinstance.py:1159} INFO - Dependencies all met for dep_context=non-requeueable deps ti=<TaskInstance: Cricbuzz_ETL3.load scheduled__2023-12-29T00:00:00+00:00 [queued]>
[2023-12-31T21:08:00.253+0530] {taskinstance.py:1159} INFO - Dependencies all met for dep_context=requeueable deps ti=<TaskInstance: Cricbuzz_ETL3.load scheduled__2023-12-29T00:00:00+00:00 [queued]>
[2023-12-31T21:08:00.254+0530] {taskinstance.py:1361} INFO - Starting attempt 1 of 1
[2023-12-31T21:08:00.267+0530] {taskinstance.py:1382} INFO - Executing <Task(PythonOperator): load> on 2023-12-29 00:00:00+00:00
[2023-12-31T21:08:00.269+0530] {standard_task_runner.py:57} INFO - Started process 20622 to run task
[2023-12-31T21:08:00.272+0530] {standard_task_runner.py:84} INFO - Running: ['airflow', 'tasks', 'run', 'Cricbuzz_ETL3', 'load', 'scheduled__2023-12-29T00:00:00+00:00', '--job-id', '461', '--raw', '--subdir', 'DAGS_FOLDER/my_dag.py', '--cfg-path', '/tmp/tmpgvz39bya']
[2023-12-31T21:08:00.273+0530] {standard_task_runner.py:85} INFO - Job 461: Subtask load
[2023-12-31T21:08:00.301+0530] {task_command.py:416} INFO - Running <TaskInstance: Cricbuzz_ETL3.load scheduled__2023-12-29T00:00:00+00:00 [running]> on host Iris
[2023-12-31T21:08:00.353+0530] {taskinstance.py:1662} INFO - Exporting env vars: AIRFLOW_CTX_DAG_OWNER='airflow' AIRFLOW_CTX_DAG_ID='Cricbuzz_ETL3' AIRFLOW_CTX_TASK_ID='load' AIRFLOW_CTX_EXECUTION_DATE='2023-12-29T00:00:00+00:00' AIRFLOW_CTX_TRY_NUMBER='1' AIRFLOW_CTX_DAG_RUN_ID='scheduled__2023-12-29T00:00:00+00:00'
[2023-12-31T21:08:00.354+0530] {taskinstance.py:1937} ERROR - Task failed with exception
Traceback (most recent call last):
  File "/home/rajabala/Desktop/projects/Airflow/airflow_env/lib/python3.9/site-packages/airflow/operators/python.py", line 192, in execute
    return_value = self.execute_callable()
  File "/home/rajabala/Desktop/projects/Airflow/airflow_env/lib/python3.9/site-packages/airflow/operators/python.py", line 209, in execute_callable
    return self.python_callable(*self.op_args, **self.op_kwargs)
TypeError: load_to_db() takes 1 positional argument but 2 were given
[2023-12-31T21:08:00.357+0530] {taskinstance.py:1400} INFO - Marking task as FAILED. dag_id=Cricbuzz_ETL3, task_id=load, execution_date=20231229T000000, start_date=20231231T153800, end_date=20231231T153800
[2023-12-31T21:08:00.368+0530] {standard_task_runner.py:104} ERROR - Failed to execute job 461 for task load (load_to_db() takes 1 positional argument but 2 were given; 20622)
[2023-12-31T21:08:00.404+0530] {local_task_job_runner.py:228} INFO - Task exited with return code 1
[2023-12-31T21:08:00.420+0530] {taskinstance.py:2778} INFO - 0 downstream tasks scheduled from follow-on schedule check
