[2023-12-31T20:56:11.630+0530] {taskinstance.py:1159} INFO - Dependencies all met for dep_context=non-requeueable deps ti=<TaskInstance: Cricbuzz_ETL1.Extract scheduled__2023-12-29T00:00:00+00:00 [queued]>
[2023-12-31T20:56:11.634+0530] {taskinstance.py:1159} INFO - Dependencies all met for dep_context=requeueable deps ti=<TaskInstance: Cricbuzz_ETL1.Extract scheduled__2023-12-29T00:00:00+00:00 [queued]>
[2023-12-31T20:56:11.635+0530] {taskinstance.py:1361} INFO - Starting attempt 2 of 2
[2023-12-31T20:56:11.647+0530] {taskinstance.py:1382} INFO - Executing <Task(PythonOperator): Extract> on 2023-12-29 00:00:00+00:00
[2023-12-31T20:56:11.650+0530] {standard_task_runner.py:57} INFO - Started process 16649 to run task
[2023-12-31T20:56:11.652+0530] {standard_task_runner.py:84} INFO - Running: ['airflow', 'tasks', 'run', 'Cricbuzz_ETL1', 'Extract', 'scheduled__2023-12-29T00:00:00+00:00', '--job-id', '438', '--raw', '--subdir', 'DAGS_FOLDER/summa.py', '--cfg-path', '/tmp/tmpvdv2a22b']
[2023-12-31T20:56:11.653+0530] {standard_task_runner.py:85} INFO - Job 438: Subtask Extract
[2023-12-31T20:56:11.680+0530] {task_command.py:416} INFO - Running <TaskInstance: Cricbuzz_ETL1.Extract scheduled__2023-12-29T00:00:00+00:00 [running]> on host Iris
[2023-12-31T20:56:11.721+0530] {taskinstance.py:1662} INFO - Exporting env vars: AIRFLOW_CTX_DAG_OWNER='airflow' AIRFLOW_CTX_DAG_ID='Cricbuzz_ETL1' AIRFLOW_CTX_TASK_ID='Extract' AIRFLOW_CTX_EXECUTION_DATE='2023-12-29T00:00:00+00:00' AIRFLOW_CTX_TRY_NUMBER='2' AIRFLOW_CTX_DAG_RUN_ID='scheduled__2023-12-29T00:00:00+00:00'
[2023-12-31T20:56:11.722+0530] {taskinstance.py:1937} ERROR - Task failed with exception
Traceback (most recent call last):
  File "/home/rajabala/Desktop/projects/Airflow/airflow_env/lib/python3.9/site-packages/airflow/operators/python.py", line 192, in execute
    return_value = self.execute_callable()
  File "/home/rajabala/Desktop/projects/Airflow/airflow_env/lib/python3.9/site-packages/airflow/operators/python.py", line 209, in execute_callable
    return self.python_callable(*self.op_args, **self.op_kwargs)
TypeError: web_scrap() takes 1 positional argument but 2 were given
[2023-12-31T20:56:11.726+0530] {taskinstance.py:1400} INFO - Marking task as FAILED. dag_id=Cricbuzz_ETL1, task_id=Extract, execution_date=20231229T000000, start_date=20231231T152611, end_date=20231231T152611
[2023-12-31T20:56:11.737+0530] {standard_task_runner.py:104} ERROR - Failed to execute job 438 for task Extract (web_scrap() takes 1 positional argument but 2 were given; 16649)
[2023-12-31T20:56:11.744+0530] {local_task_job_runner.py:228} INFO - Task exited with return code 1
[2023-12-31T20:56:11.758+0530] {taskinstance.py:2778} INFO - 0 downstream tasks scheduled from follow-on schedule check
