[2023-12-31T21:08:16.523+0530] {taskinstance.py:1159} INFO - Dependencies all met for dep_context=non-requeueable deps ti=<TaskInstance: Cricbuzz_ETL.load scheduled__2023-12-30T00:00:00+00:00 [queued]>
[2023-12-31T21:08:16.532+0530] {taskinstance.py:1159} INFO - Dependencies all met for dep_context=requeueable deps ti=<TaskInstance: Cricbuzz_ETL.load scheduled__2023-12-30T00:00:00+00:00 [queued]>
[2023-12-31T21:08:16.532+0530] {taskinstance.py:1361} INFO - Starting attempt 1 of 1
[2023-12-31T21:08:16.548+0530] {taskinstance.py:1382} INFO - Executing <Task(PythonOperator): load> on 2023-12-30 00:00:00+00:00
[2023-12-31T21:08:16.551+0530] {standard_task_runner.py:57} INFO - Started process 20844 to run task
[2023-12-31T21:08:16.555+0530] {standard_task_runner.py:84} INFO - Running: ['airflow', 'tasks', 'run', 'Cricbuzz_ETL', 'load', 'scheduled__2023-12-30T00:00:00+00:00', '--job-id', '469', '--raw', '--subdir', 'DAGS_FOLDER/Crickbuzz_dag.py', '--cfg-path', '/tmp/tmpd5sa7kef']
[2023-12-31T21:08:16.556+0530] {standard_task_runner.py:85} INFO - Job 469: Subtask load
[2023-12-31T21:08:16.614+0530] {task_command.py:416} INFO - Running <TaskInstance: Cricbuzz_ETL.load scheduled__2023-12-30T00:00:00+00:00 [running]> on host Iris
[2023-12-31T21:08:16.717+0530] {taskinstance.py:1662} INFO - Exporting env vars: AIRFLOW_CTX_DAG_OWNER='airflow' AIRFLOW_CTX_DAG_ID='Cricbuzz_ETL' AIRFLOW_CTX_TASK_ID='load' AIRFLOW_CTX_EXECUTION_DATE='2023-12-30T00:00:00+00:00' AIRFLOW_CTX_TRY_NUMBER='1' AIRFLOW_CTX_DAG_RUN_ID='scheduled__2023-12-30T00:00:00+00:00'
[2023-12-31T21:08:17.091+0530] {taskinstance.py:1937} ERROR - Task failed with exception
Traceback (most recent call last):
  File "/home/rajabala/Desktop/projects/Airflow/airflow_env/lib/python3.9/site-packages/sqlalchemy/engine/base.py", line 3371, in _wrap_pool_connect
    return fn()
  File "/home/rajabala/Desktop/projects/Airflow/airflow_env/lib/python3.9/site-packages/sqlalchemy/pool/base.py", line 327, in connect
    return _ConnectionFairy._checkout(self)
  File "/home/rajabala/Desktop/projects/Airflow/airflow_env/lib/python3.9/site-packages/sqlalchemy/pool/base.py", line 894, in _checkout
    fairy = _ConnectionRecord.checkout(pool)
  File "/home/rajabala/Desktop/projects/Airflow/airflow_env/lib/python3.9/site-packages/sqlalchemy/pool/base.py", line 493, in checkout
    rec = pool._do_get()
  File "/home/rajabala/Desktop/projects/Airflow/airflow_env/lib/python3.9/site-packages/sqlalchemy/pool/impl.py", line 146, in _do_get
    self._dec_overflow()
  File "/home/rajabala/Desktop/projects/Airflow/airflow_env/lib/python3.9/site-packages/sqlalchemy/util/langhelpers.py", line 70, in __exit__
    compat.raise_(
  File "/home/rajabala/Desktop/projects/Airflow/airflow_env/lib/python3.9/site-packages/sqlalchemy/util/compat.py", line 211, in raise_
    raise exception
  File "/home/rajabala/Desktop/projects/Airflow/airflow_env/lib/python3.9/site-packages/sqlalchemy/pool/impl.py", line 143, in _do_get
    return self._create_connection()
  File "/home/rajabala/Desktop/projects/Airflow/airflow_env/lib/python3.9/site-packages/sqlalchemy/pool/base.py", line 273, in _create_connection
    return _ConnectionRecord(self)
  File "/home/rajabala/Desktop/projects/Airflow/airflow_env/lib/python3.9/site-packages/sqlalchemy/pool/base.py", line 388, in __init__
    self.__connect()
  File "/home/rajabala/Desktop/projects/Airflow/airflow_env/lib/python3.9/site-packages/sqlalchemy/pool/base.py", line 691, in __connect
    pool.logger.debug("Error on connect(): %s", e)
  File "/home/rajabala/Desktop/projects/Airflow/airflow_env/lib/python3.9/site-packages/sqlalchemy/util/langhelpers.py", line 70, in __exit__
    compat.raise_(
  File "/home/rajabala/Desktop/projects/Airflow/airflow_env/lib/python3.9/site-packages/sqlalchemy/util/compat.py", line 211, in raise_
    raise exception
  File "/home/rajabala/Desktop/projects/Airflow/airflow_env/lib/python3.9/site-packages/sqlalchemy/pool/base.py", line 686, in __connect
    self.dbapi_connection = connection = pool._invoke_creator(self)
  File "/home/rajabala/Desktop/projects/Airflow/airflow_env/lib/python3.9/site-packages/sqlalchemy/engine/create.py", line 574, in connect
    return dialect.connect(*cargs, **cparams)
  File "/home/rajabala/Desktop/projects/Airflow/airflow_env/lib/python3.9/site-packages/sqlalchemy/engine/default.py", line 598, in connect
    return self.dbapi.connect(*cargs, **cparams)
  File "/home/rajabala/Desktop/projects/Airflow/airflow_env/lib/python3.9/site-packages/psycopg2/__init__.py", line 122, in connect
    conn = _connect(dsn, connection_factory=connection_factory, **kwasync)
psycopg2.OperationalError: could not translate host name "postgres" to address: Temporary failure in name resolution


The above exception was the direct cause of the following exception:

Traceback (most recent call last):
  File "/home/rajabala/Desktop/projects/Airflow/airflow_env/lib/python3.9/site-packages/airflow/operators/python.py", line 192, in execute
    return_value = self.execute_callable()
  File "/home/rajabala/Desktop/projects/Airflow/airflow_env/lib/python3.9/site-packages/airflow/operators/python.py", line 209, in execute_callable
    return self.python_callable(*self.op_args, **self.op_kwargs)
  File "/home/rajabala/Desktop/projects/Airflow/dags/Cricbuzz_files/Load.py", line 33, in load_to_db
    conn = db.connect()
  File "/home/rajabala/Desktop/projects/Airflow/airflow_env/lib/python3.9/site-packages/sqlalchemy/engine/base.py", line 3325, in connect
    return self._connection_cls(self, close_with_result=close_with_result)
  File "/home/rajabala/Desktop/projects/Airflow/airflow_env/lib/python3.9/site-packages/sqlalchemy/engine/base.py", line 96, in __init__
    else engine.raw_connection()
  File "/home/rajabala/Desktop/projects/Airflow/airflow_env/lib/python3.9/site-packages/sqlalchemy/engine/base.py", line 3404, in raw_connection
    return self._wrap_pool_connect(self.pool.connect, _connection)
  File "/home/rajabala/Desktop/projects/Airflow/airflow_env/lib/python3.9/site-packages/sqlalchemy/engine/base.py", line 3374, in _wrap_pool_connect
    Connection._handle_dbapi_exception_noconnection(
  File "/home/rajabala/Desktop/projects/Airflow/airflow_env/lib/python3.9/site-packages/sqlalchemy/engine/base.py", line 2208, in _handle_dbapi_exception_noconnection
    util.raise_(
  File "/home/rajabala/Desktop/projects/Airflow/airflow_env/lib/python3.9/site-packages/sqlalchemy/util/compat.py", line 211, in raise_
    raise exception
  File "/home/rajabala/Desktop/projects/Airflow/airflow_env/lib/python3.9/site-packages/sqlalchemy/engine/base.py", line 3371, in _wrap_pool_connect
    return fn()
  File "/home/rajabala/Desktop/projects/Airflow/airflow_env/lib/python3.9/site-packages/sqlalchemy/pool/base.py", line 327, in connect
    return _ConnectionFairy._checkout(self)
  File "/home/rajabala/Desktop/projects/Airflow/airflow_env/lib/python3.9/site-packages/sqlalchemy/pool/base.py", line 894, in _checkout
    fairy = _ConnectionRecord.checkout(pool)
  File "/home/rajabala/Desktop/projects/Airflow/airflow_env/lib/python3.9/site-packages/sqlalchemy/pool/base.py", line 493, in checkout
    rec = pool._do_get()
  File "/home/rajabala/Desktop/projects/Airflow/airflow_env/lib/python3.9/site-packages/sqlalchemy/pool/impl.py", line 146, in _do_get
    self._dec_overflow()
  File "/home/rajabala/Desktop/projects/Airflow/airflow_env/lib/python3.9/site-packages/sqlalchemy/util/langhelpers.py", line 70, in __exit__
    compat.raise_(
  File "/home/rajabala/Desktop/projects/Airflow/airflow_env/lib/python3.9/site-packages/sqlalchemy/util/compat.py", line 211, in raise_
    raise exception
  File "/home/rajabala/Desktop/projects/Airflow/airflow_env/lib/python3.9/site-packages/sqlalchemy/pool/impl.py", line 143, in _do_get
    return self._create_connection()
  File "/home/rajabala/Desktop/projects/Airflow/airflow_env/lib/python3.9/site-packages/sqlalchemy/pool/base.py", line 273, in _create_connection
    return _ConnectionRecord(self)
  File "/home/rajabala/Desktop/projects/Airflow/airflow_env/lib/python3.9/site-packages/sqlalchemy/pool/base.py", line 388, in __init__
    self.__connect()
  File "/home/rajabala/Desktop/projects/Airflow/airflow_env/lib/python3.9/site-packages/sqlalchemy/pool/base.py", line 691, in __connect
    pool.logger.debug("Error on connect(): %s", e)
  File "/home/rajabala/Desktop/projects/Airflow/airflow_env/lib/python3.9/site-packages/sqlalchemy/util/langhelpers.py", line 70, in __exit__
    compat.raise_(
  File "/home/rajabala/Desktop/projects/Airflow/airflow_env/lib/python3.9/site-packages/sqlalchemy/util/compat.py", line 211, in raise_
    raise exception
  File "/home/rajabala/Desktop/projects/Airflow/airflow_env/lib/python3.9/site-packages/sqlalchemy/pool/base.py", line 686, in __connect
    self.dbapi_connection = connection = pool._invoke_creator(self)
  File "/home/rajabala/Desktop/projects/Airflow/airflow_env/lib/python3.9/site-packages/sqlalchemy/engine/create.py", line 574, in connect
    return dialect.connect(*cargs, **cparams)
  File "/home/rajabala/Desktop/projects/Airflow/airflow_env/lib/python3.9/site-packages/sqlalchemy/engine/default.py", line 598, in connect
    return self.dbapi.connect(*cargs, **cparams)
  File "/home/rajabala/Desktop/projects/Airflow/airflow_env/lib/python3.9/site-packages/psycopg2/__init__.py", line 122, in connect
    conn = _connect(dsn, connection_factory=connection_factory, **kwasync)
sqlalchemy.exc.OperationalError: (psycopg2.OperationalError) could not translate host name "postgres" to address: Temporary failure in name resolution

(Background on this error at: https://sqlalche.me/e/14/e3q8)
[2023-12-31T21:08:17.097+0530] {taskinstance.py:1400} INFO - Marking task as FAILED. dag_id=Cricbuzz_ETL, task_id=load, execution_date=20231230T000000, start_date=20231231T153816, end_date=20231231T153817
[2023-12-31T21:08:17.109+0530] {standard_task_runner.py:104} ERROR - Failed to execute job 469 for task load ((psycopg2.OperationalError) could not translate host name "postgres" to address: Temporary failure in name resolution

(Background on this error at: https://sqlalche.me/e/14/e3q8); 20844)
[2023-12-31T21:08:17.128+0530] {local_task_job_runner.py:228} INFO - Task exited with return code 1
[2023-12-31T21:08:17.142+0530] {taskinstance.py:2778} INFO - 0 downstream tasks scheduled from follow-on schedule check
[2024-01-02T17:20:55.910+0530] {taskinstance.py:1159} INFO - Dependencies all met for dep_context=non-requeueable deps ti=<TaskInstance: Cricbuzz_ETL.load scheduled__2023-12-30T00:00:00+00:00 [queued]>
[2024-01-02T17:20:55.917+0530] {taskinstance.py:1159} INFO - Dependencies all met for dep_context=requeueable deps ti=<TaskInstance: Cricbuzz_ETL.load scheduled__2023-12-30T00:00:00+00:00 [queued]>
[2024-01-02T17:20:55.917+0530] {taskinstance.py:1361} INFO - Starting attempt 1 of 1
[2024-01-02T17:20:55.929+0530] {taskinstance.py:1382} INFO - Executing <Task(PythonOperator): load> on 2023-12-30 00:00:00+00:00
[2024-01-02T17:20:55.932+0530] {standard_task_runner.py:57} INFO - Started process 11907 to run task
[2024-01-02T17:20:55.935+0530] {standard_task_runner.py:84} INFO - Running: ['airflow', 'tasks', 'run', 'Cricbuzz_ETL', 'load', 'scheduled__2023-12-30T00:00:00+00:00', '--job-id', '543', '--raw', '--subdir', 'DAGS_FOLDER/Crickbuzz_dag.py', '--cfg-path', '/tmp/tmph_43g0up']
[2024-01-02T17:20:55.936+0530] {standard_task_runner.py:85} INFO - Job 543: Subtask load
[2024-01-02T17:20:55.965+0530] {task_command.py:416} INFO - Running <TaskInstance: Cricbuzz_ETL.load scheduled__2023-12-30T00:00:00+00:00 [running]> on host Iris
[2024-01-02T17:20:56.012+0530] {taskinstance.py:1662} INFO - Exporting env vars: AIRFLOW_CTX_DAG_OWNER='airflow' AIRFLOW_CTX_DAG_ID='Cricbuzz_ETL' AIRFLOW_CTX_TASK_ID='load' AIRFLOW_CTX_EXECUTION_DATE='2023-12-30T00:00:00+00:00' AIRFLOW_CTX_TRY_NUMBER='1' AIRFLOW_CTX_DAG_RUN_ID='scheduled__2023-12-30T00:00:00+00:00'
[2024-01-02T17:20:56.341+0530] {taskinstance.py:1937} ERROR - Task failed with exception
Traceback (most recent call last):
  File "/home/rajabala/Desktop/projects/Airflow/airflow_env/lib/python3.9/site-packages/sqlalchemy/engine/base.py", line 3371, in _wrap_pool_connect
    return fn()
  File "/home/rajabala/Desktop/projects/Airflow/airflow_env/lib/python3.9/site-packages/sqlalchemy/pool/base.py", line 327, in connect
    return _ConnectionFairy._checkout(self)
  File "/home/rajabala/Desktop/projects/Airflow/airflow_env/lib/python3.9/site-packages/sqlalchemy/pool/base.py", line 894, in _checkout
    fairy = _ConnectionRecord.checkout(pool)
  File "/home/rajabala/Desktop/projects/Airflow/airflow_env/lib/python3.9/site-packages/sqlalchemy/pool/base.py", line 493, in checkout
    rec = pool._do_get()
  File "/home/rajabala/Desktop/projects/Airflow/airflow_env/lib/python3.9/site-packages/sqlalchemy/pool/impl.py", line 146, in _do_get
    self._dec_overflow()
  File "/home/rajabala/Desktop/projects/Airflow/airflow_env/lib/python3.9/site-packages/sqlalchemy/util/langhelpers.py", line 70, in __exit__
    compat.raise_(
  File "/home/rajabala/Desktop/projects/Airflow/airflow_env/lib/python3.9/site-packages/sqlalchemy/util/compat.py", line 211, in raise_
    raise exception
  File "/home/rajabala/Desktop/projects/Airflow/airflow_env/lib/python3.9/site-packages/sqlalchemy/pool/impl.py", line 143, in _do_get
    return self._create_connection()
  File "/home/rajabala/Desktop/projects/Airflow/airflow_env/lib/python3.9/site-packages/sqlalchemy/pool/base.py", line 273, in _create_connection
    return _ConnectionRecord(self)
  File "/home/rajabala/Desktop/projects/Airflow/airflow_env/lib/python3.9/site-packages/sqlalchemy/pool/base.py", line 388, in __init__
    self.__connect()
  File "/home/rajabala/Desktop/projects/Airflow/airflow_env/lib/python3.9/site-packages/sqlalchemy/pool/base.py", line 691, in __connect
    pool.logger.debug("Error on connect(): %s", e)
  File "/home/rajabala/Desktop/projects/Airflow/airflow_env/lib/python3.9/site-packages/sqlalchemy/util/langhelpers.py", line 70, in __exit__
    compat.raise_(
  File "/home/rajabala/Desktop/projects/Airflow/airflow_env/lib/python3.9/site-packages/sqlalchemy/util/compat.py", line 211, in raise_
    raise exception
  File "/home/rajabala/Desktop/projects/Airflow/airflow_env/lib/python3.9/site-packages/sqlalchemy/pool/base.py", line 686, in __connect
    self.dbapi_connection = connection = pool._invoke_creator(self)
  File "/home/rajabala/Desktop/projects/Airflow/airflow_env/lib/python3.9/site-packages/sqlalchemy/engine/create.py", line 574, in connect
    return dialect.connect(*cargs, **cparams)
  File "/home/rajabala/Desktop/projects/Airflow/airflow_env/lib/python3.9/site-packages/sqlalchemy/engine/default.py", line 598, in connect
    return self.dbapi.connect(*cargs, **cparams)
  File "/home/rajabala/Desktop/projects/Airflow/airflow_env/lib/python3.9/site-packages/psycopg2/__init__.py", line 122, in connect
    conn = _connect(dsn, connection_factory=connection_factory, **kwasync)
psycopg2.OperationalError: could not translate host name "postgres" to address: Temporary failure in name resolution


The above exception was the direct cause of the following exception:

Traceback (most recent call last):
  File "/home/rajabala/Desktop/projects/Airflow/airflow_env/lib/python3.9/site-packages/airflow/operators/python.py", line 192, in execute
    return_value = self.execute_callable()
  File "/home/rajabala/Desktop/projects/Airflow/airflow_env/lib/python3.9/site-packages/airflow/operators/python.py", line 209, in execute_callable
    return self.python_callable(*self.op_args, **self.op_kwargs)
  File "/home/rajabala/Desktop/projects/Airflow/dags/Cricbuzz_files/Load.py", line 33, in load_to_db
    conn = db.connect()
  File "/home/rajabala/Desktop/projects/Airflow/airflow_env/lib/python3.9/site-packages/sqlalchemy/engine/base.py", line 3325, in connect
    return self._connection_cls(self, close_with_result=close_with_result)
  File "/home/rajabala/Desktop/projects/Airflow/airflow_env/lib/python3.9/site-packages/sqlalchemy/engine/base.py", line 96, in __init__
    else engine.raw_connection()
  File "/home/rajabala/Desktop/projects/Airflow/airflow_env/lib/python3.9/site-packages/sqlalchemy/engine/base.py", line 3404, in raw_connection
    return self._wrap_pool_connect(self.pool.connect, _connection)
  File "/home/rajabala/Desktop/projects/Airflow/airflow_env/lib/python3.9/site-packages/sqlalchemy/engine/base.py", line 3374, in _wrap_pool_connect
    Connection._handle_dbapi_exception_noconnection(
  File "/home/rajabala/Desktop/projects/Airflow/airflow_env/lib/python3.9/site-packages/sqlalchemy/engine/base.py", line 2208, in _handle_dbapi_exception_noconnection
    util.raise_(
  File "/home/rajabala/Desktop/projects/Airflow/airflow_env/lib/python3.9/site-packages/sqlalchemy/util/compat.py", line 211, in raise_
    raise exception
  File "/home/rajabala/Desktop/projects/Airflow/airflow_env/lib/python3.9/site-packages/sqlalchemy/engine/base.py", line 3371, in _wrap_pool_connect
    return fn()
  File "/home/rajabala/Desktop/projects/Airflow/airflow_env/lib/python3.9/site-packages/sqlalchemy/pool/base.py", line 327, in connect
    return _ConnectionFairy._checkout(self)
  File "/home/rajabala/Desktop/projects/Airflow/airflow_env/lib/python3.9/site-packages/sqlalchemy/pool/base.py", line 894, in _checkout
    fairy = _ConnectionRecord.checkout(pool)
  File "/home/rajabala/Desktop/projects/Airflow/airflow_env/lib/python3.9/site-packages/sqlalchemy/pool/base.py", line 493, in checkout
    rec = pool._do_get()
  File "/home/rajabala/Desktop/projects/Airflow/airflow_env/lib/python3.9/site-packages/sqlalchemy/pool/impl.py", line 146, in _do_get
    self._dec_overflow()
  File "/home/rajabala/Desktop/projects/Airflow/airflow_env/lib/python3.9/site-packages/sqlalchemy/util/langhelpers.py", line 70, in __exit__
    compat.raise_(
  File "/home/rajabala/Desktop/projects/Airflow/airflow_env/lib/python3.9/site-packages/sqlalchemy/util/compat.py", line 211, in raise_
    raise exception
  File "/home/rajabala/Desktop/projects/Airflow/airflow_env/lib/python3.9/site-packages/sqlalchemy/pool/impl.py", line 143, in _do_get
    return self._create_connection()
  File "/home/rajabala/Desktop/projects/Airflow/airflow_env/lib/python3.9/site-packages/sqlalchemy/pool/base.py", line 273, in _create_connection
    return _ConnectionRecord(self)
  File "/home/rajabala/Desktop/projects/Airflow/airflow_env/lib/python3.9/site-packages/sqlalchemy/pool/base.py", line 388, in __init__
    self.__connect()
  File "/home/rajabala/Desktop/projects/Airflow/airflow_env/lib/python3.9/site-packages/sqlalchemy/pool/base.py", line 691, in __connect
    pool.logger.debug("Error on connect(): %s", e)
  File "/home/rajabala/Desktop/projects/Airflow/airflow_env/lib/python3.9/site-packages/sqlalchemy/util/langhelpers.py", line 70, in __exit__
    compat.raise_(
  File "/home/rajabala/Desktop/projects/Airflow/airflow_env/lib/python3.9/site-packages/sqlalchemy/util/compat.py", line 211, in raise_
    raise exception
  File "/home/rajabala/Desktop/projects/Airflow/airflow_env/lib/python3.9/site-packages/sqlalchemy/pool/base.py", line 686, in __connect
    self.dbapi_connection = connection = pool._invoke_creator(self)
  File "/home/rajabala/Desktop/projects/Airflow/airflow_env/lib/python3.9/site-packages/sqlalchemy/engine/create.py", line 574, in connect
    return dialect.connect(*cargs, **cparams)
  File "/home/rajabala/Desktop/projects/Airflow/airflow_env/lib/python3.9/site-packages/sqlalchemy/engine/default.py", line 598, in connect
    return self.dbapi.connect(*cargs, **cparams)
  File "/home/rajabala/Desktop/projects/Airflow/airflow_env/lib/python3.9/site-packages/psycopg2/__init__.py", line 122, in connect
    conn = _connect(dsn, connection_factory=connection_factory, **kwasync)
sqlalchemy.exc.OperationalError: (psycopg2.OperationalError) could not translate host name "postgres" to address: Temporary failure in name resolution

(Background on this error at: https://sqlalche.me/e/14/e3q8)
[2024-01-02T17:20:56.346+0530] {taskinstance.py:1400} INFO - Marking task as FAILED. dag_id=Cricbuzz_ETL, task_id=load, execution_date=20231230T000000, start_date=20240102T115055, end_date=20240102T115056
[2024-01-02T17:20:56.357+0530] {standard_task_runner.py:104} ERROR - Failed to execute job 543 for task load ((psycopg2.OperationalError) could not translate host name "postgres" to address: Temporary failure in name resolution

(Background on this error at: https://sqlalche.me/e/14/e3q8); 11907)
[2024-01-02T17:20:56.387+0530] {local_task_job_runner.py:228} INFO - Task exited with return code 1
[2024-01-02T17:20:56.404+0530] {taskinstance.py:2778} INFO - 0 downstream tasks scheduled from follow-on schedule check
[2024-01-02T17:26:50.032+0530] {taskinstance.py:1159} INFO - Dependencies all met for dep_context=non-requeueable deps ti=<TaskInstance: Cricbuzz_ETL.load scheduled__2023-12-30T00:00:00+00:00 [queued]>
[2024-01-02T17:26:50.038+0530] {taskinstance.py:1159} INFO - Dependencies all met for dep_context=requeueable deps ti=<TaskInstance: Cricbuzz_ETL.load scheduled__2023-12-30T00:00:00+00:00 [queued]>
[2024-01-02T17:26:50.038+0530] {taskinstance.py:1361} INFO - Starting attempt 1 of 1
[2024-01-02T17:26:50.051+0530] {taskinstance.py:1382} INFO - Executing <Task(PythonOperator): load> on 2023-12-30 00:00:00+00:00
[2024-01-02T17:26:50.053+0530] {standard_task_runner.py:57} INFO - Started process 14845 to run task
[2024-01-02T17:26:50.056+0530] {standard_task_runner.py:84} INFO - Running: ['airflow', 'tasks', 'run', 'Cricbuzz_ETL', 'load', 'scheduled__2023-12-30T00:00:00+00:00', '--job-id', '547', '--raw', '--subdir', 'DAGS_FOLDER/Crickbuzz_dag.py', '--cfg-path', '/tmp/tmp9k8oi391']
[2024-01-02T17:26:50.057+0530] {standard_task_runner.py:85} INFO - Job 547: Subtask load
[2024-01-02T17:26:50.086+0530] {task_command.py:416} INFO - Running <TaskInstance: Cricbuzz_ETL.load scheduled__2023-12-30T00:00:00+00:00 [running]> on host Iris
[2024-01-02T17:26:50.143+0530] {taskinstance.py:1662} INFO - Exporting env vars: AIRFLOW_CTX_DAG_OWNER='airflow' AIRFLOW_CTX_DAG_ID='Cricbuzz_ETL' AIRFLOW_CTX_TASK_ID='load' AIRFLOW_CTX_EXECUTION_DATE='2023-12-30T00:00:00+00:00' AIRFLOW_CTX_TRY_NUMBER='1' AIRFLOW_CTX_DAG_RUN_ID='scheduled__2023-12-30T00:00:00+00:00'
[2024-01-02T17:26:50.497+0530] {taskinstance.py:1937} ERROR - Task failed with exception
Traceback (most recent call last):
  File "/home/rajabala/Desktop/projects/Airflow/airflow_env/lib/python3.9/site-packages/sqlalchemy/engine/base.py", line 3371, in _wrap_pool_connect
    return fn()
  File "/home/rajabala/Desktop/projects/Airflow/airflow_env/lib/python3.9/site-packages/sqlalchemy/pool/base.py", line 327, in connect
    return _ConnectionFairy._checkout(self)
  File "/home/rajabala/Desktop/projects/Airflow/airflow_env/lib/python3.9/site-packages/sqlalchemy/pool/base.py", line 894, in _checkout
    fairy = _ConnectionRecord.checkout(pool)
  File "/home/rajabala/Desktop/projects/Airflow/airflow_env/lib/python3.9/site-packages/sqlalchemy/pool/base.py", line 493, in checkout
    rec = pool._do_get()
  File "/home/rajabala/Desktop/projects/Airflow/airflow_env/lib/python3.9/site-packages/sqlalchemy/pool/impl.py", line 146, in _do_get
    self._dec_overflow()
  File "/home/rajabala/Desktop/projects/Airflow/airflow_env/lib/python3.9/site-packages/sqlalchemy/util/langhelpers.py", line 70, in __exit__
    compat.raise_(
  File "/home/rajabala/Desktop/projects/Airflow/airflow_env/lib/python3.9/site-packages/sqlalchemy/util/compat.py", line 211, in raise_
    raise exception
  File "/home/rajabala/Desktop/projects/Airflow/airflow_env/lib/python3.9/site-packages/sqlalchemy/pool/impl.py", line 143, in _do_get
    return self._create_connection()
  File "/home/rajabala/Desktop/projects/Airflow/airflow_env/lib/python3.9/site-packages/sqlalchemy/pool/base.py", line 273, in _create_connection
    return _ConnectionRecord(self)
  File "/home/rajabala/Desktop/projects/Airflow/airflow_env/lib/python3.9/site-packages/sqlalchemy/pool/base.py", line 388, in __init__
    self.__connect()
  File "/home/rajabala/Desktop/projects/Airflow/airflow_env/lib/python3.9/site-packages/sqlalchemy/pool/base.py", line 691, in __connect
    pool.logger.debug("Error on connect(): %s", e)
  File "/home/rajabala/Desktop/projects/Airflow/airflow_env/lib/python3.9/site-packages/sqlalchemy/util/langhelpers.py", line 70, in __exit__
    compat.raise_(
  File "/home/rajabala/Desktop/projects/Airflow/airflow_env/lib/python3.9/site-packages/sqlalchemy/util/compat.py", line 211, in raise_
    raise exception
  File "/home/rajabala/Desktop/projects/Airflow/airflow_env/lib/python3.9/site-packages/sqlalchemy/pool/base.py", line 686, in __connect
    self.dbapi_connection = connection = pool._invoke_creator(self)
  File "/home/rajabala/Desktop/projects/Airflow/airflow_env/lib/python3.9/site-packages/sqlalchemy/engine/create.py", line 574, in connect
    return dialect.connect(*cargs, **cparams)
  File "/home/rajabala/Desktop/projects/Airflow/airflow_env/lib/python3.9/site-packages/sqlalchemy/engine/default.py", line 598, in connect
    return self.dbapi.connect(*cargs, **cparams)
  File "/home/rajabala/Desktop/projects/Airflow/airflow_env/lib/python3.9/site-packages/psycopg2/__init__.py", line 122, in connect
    conn = _connect(dsn, connection_factory=connection_factory, **kwasync)
psycopg2.OperationalError: could not translate host name "postgres" to address: Temporary failure in name resolution


The above exception was the direct cause of the following exception:

Traceback (most recent call last):
  File "/home/rajabala/Desktop/projects/Airflow/airflow_env/lib/python3.9/site-packages/airflow/operators/python.py", line 192, in execute
    return_value = self.execute_callable()
  File "/home/rajabala/Desktop/projects/Airflow/airflow_env/lib/python3.9/site-packages/airflow/operators/python.py", line 209, in execute_callable
    return self.python_callable(*self.op_args, **self.op_kwargs)
  File "/home/rajabala/Desktop/projects/Airflow/dags/Cricbuzz_files/Load.py", line 33, in load_to_db
    conn = db.connect()
  File "/home/rajabala/Desktop/projects/Airflow/airflow_env/lib/python3.9/site-packages/sqlalchemy/engine/base.py", line 3325, in connect
    return self._connection_cls(self, close_with_result=close_with_result)
  File "/home/rajabala/Desktop/projects/Airflow/airflow_env/lib/python3.9/site-packages/sqlalchemy/engine/base.py", line 96, in __init__
    else engine.raw_connection()
  File "/home/rajabala/Desktop/projects/Airflow/airflow_env/lib/python3.9/site-packages/sqlalchemy/engine/base.py", line 3404, in raw_connection
    return self._wrap_pool_connect(self.pool.connect, _connection)
  File "/home/rajabala/Desktop/projects/Airflow/airflow_env/lib/python3.9/site-packages/sqlalchemy/engine/base.py", line 3374, in _wrap_pool_connect
    Connection._handle_dbapi_exception_noconnection(
  File "/home/rajabala/Desktop/projects/Airflow/airflow_env/lib/python3.9/site-packages/sqlalchemy/engine/base.py", line 2208, in _handle_dbapi_exception_noconnection
    util.raise_(
  File "/home/rajabala/Desktop/projects/Airflow/airflow_env/lib/python3.9/site-packages/sqlalchemy/util/compat.py", line 211, in raise_
    raise exception
  File "/home/rajabala/Desktop/projects/Airflow/airflow_env/lib/python3.9/site-packages/sqlalchemy/engine/base.py", line 3371, in _wrap_pool_connect
    return fn()
  File "/home/rajabala/Desktop/projects/Airflow/airflow_env/lib/python3.9/site-packages/sqlalchemy/pool/base.py", line 327, in connect
    return _ConnectionFairy._checkout(self)
  File "/home/rajabala/Desktop/projects/Airflow/airflow_env/lib/python3.9/site-packages/sqlalchemy/pool/base.py", line 894, in _checkout
    fairy = _ConnectionRecord.checkout(pool)
  File "/home/rajabala/Desktop/projects/Airflow/airflow_env/lib/python3.9/site-packages/sqlalchemy/pool/base.py", line 493, in checkout
    rec = pool._do_get()
  File "/home/rajabala/Desktop/projects/Airflow/airflow_env/lib/python3.9/site-packages/sqlalchemy/pool/impl.py", line 146, in _do_get
    self._dec_overflow()
  File "/home/rajabala/Desktop/projects/Airflow/airflow_env/lib/python3.9/site-packages/sqlalchemy/util/langhelpers.py", line 70, in __exit__
    compat.raise_(
  File "/home/rajabala/Desktop/projects/Airflow/airflow_env/lib/python3.9/site-packages/sqlalchemy/util/compat.py", line 211, in raise_
    raise exception
  File "/home/rajabala/Desktop/projects/Airflow/airflow_env/lib/python3.9/site-packages/sqlalchemy/pool/impl.py", line 143, in _do_get
    return self._create_connection()
  File "/home/rajabala/Desktop/projects/Airflow/airflow_env/lib/python3.9/site-packages/sqlalchemy/pool/base.py", line 273, in _create_connection
    return _ConnectionRecord(self)
  File "/home/rajabala/Desktop/projects/Airflow/airflow_env/lib/python3.9/site-packages/sqlalchemy/pool/base.py", line 388, in __init__
    self.__connect()
  File "/home/rajabala/Desktop/projects/Airflow/airflow_env/lib/python3.9/site-packages/sqlalchemy/pool/base.py", line 691, in __connect
    pool.logger.debug("Error on connect(): %s", e)
  File "/home/rajabala/Desktop/projects/Airflow/airflow_env/lib/python3.9/site-packages/sqlalchemy/util/langhelpers.py", line 70, in __exit__
    compat.raise_(
  File "/home/rajabala/Desktop/projects/Airflow/airflow_env/lib/python3.9/site-packages/sqlalchemy/util/compat.py", line 211, in raise_
    raise exception
  File "/home/rajabala/Desktop/projects/Airflow/airflow_env/lib/python3.9/site-packages/sqlalchemy/pool/base.py", line 686, in __connect
    self.dbapi_connection = connection = pool._invoke_creator(self)
  File "/home/rajabala/Desktop/projects/Airflow/airflow_env/lib/python3.9/site-packages/sqlalchemy/engine/create.py", line 574, in connect
    return dialect.connect(*cargs, **cparams)
  File "/home/rajabala/Desktop/projects/Airflow/airflow_env/lib/python3.9/site-packages/sqlalchemy/engine/default.py", line 598, in connect
    return self.dbapi.connect(*cargs, **cparams)
  File "/home/rajabala/Desktop/projects/Airflow/airflow_env/lib/python3.9/site-packages/psycopg2/__init__.py", line 122, in connect
    conn = _connect(dsn, connection_factory=connection_factory, **kwasync)
sqlalchemy.exc.OperationalError: (psycopg2.OperationalError) could not translate host name "postgres" to address: Temporary failure in name resolution

(Background on this error at: https://sqlalche.me/e/14/e3q8)
[2024-01-02T17:26:50.505+0530] {taskinstance.py:1400} INFO - Marking task as FAILED. dag_id=Cricbuzz_ETL, task_id=load, execution_date=20231230T000000, start_date=20240102T115650, end_date=20240102T115650
[2024-01-02T17:26:50.520+0530] {standard_task_runner.py:104} ERROR - Failed to execute job 547 for task load ((psycopg2.OperationalError) could not translate host name "postgres" to address: Temporary failure in name resolution

(Background on this error at: https://sqlalche.me/e/14/e3q8); 14845)
[2024-01-02T17:26:50.549+0530] {local_task_job_runner.py:228} INFO - Task exited with return code 1
[2024-01-02T17:26:50.563+0530] {taskinstance.py:2778} INFO - 0 downstream tasks scheduled from follow-on schedule check
[2024-01-02T17:55:17.717+0530] {taskinstance.py:1159} INFO - Dependencies all met for dep_context=non-requeueable deps ti=<TaskInstance: Cricbuzz_ETL.load scheduled__2023-12-30T00:00:00+00:00 [queued]>
[2024-01-02T17:55:17.725+0530] {taskinstance.py:1159} INFO - Dependencies all met for dep_context=requeueable deps ti=<TaskInstance: Cricbuzz_ETL.load scheduled__2023-12-30T00:00:00+00:00 [queued]>
[2024-01-02T17:55:17.725+0530] {taskinstance.py:1361} INFO - Starting attempt 1 of 1
[2024-01-02T17:55:17.738+0530] {taskinstance.py:1382} INFO - Executing <Task(PythonOperator): load> on 2023-12-30 00:00:00+00:00
[2024-01-02T17:55:17.740+0530] {standard_task_runner.py:57} INFO - Started process 25148 to run task
[2024-01-02T17:55:17.743+0530] {standard_task_runner.py:84} INFO - Running: ['airflow', 'tasks', 'run', 'Cricbuzz_ETL', 'load', 'scheduled__2023-12-30T00:00:00+00:00', '--job-id', '552', '--raw', '--subdir', 'DAGS_FOLDER/Crickbuzz_dag.py', '--cfg-path', '/tmp/tmpxkm2mo1y']
[2024-01-02T17:55:17.744+0530] {standard_task_runner.py:85} INFO - Job 552: Subtask load
[2024-01-02T17:55:17.776+0530] {task_command.py:416} INFO - Running <TaskInstance: Cricbuzz_ETL.load scheduled__2023-12-30T00:00:00+00:00 [running]> on host Iris
[2024-01-02T17:55:17.836+0530] {taskinstance.py:1662} INFO - Exporting env vars: AIRFLOW_CTX_DAG_OWNER='airflow' AIRFLOW_CTX_DAG_ID='Cricbuzz_ETL' AIRFLOW_CTX_TASK_ID='load' AIRFLOW_CTX_EXECUTION_DATE='2023-12-30T00:00:00+00:00' AIRFLOW_CTX_TRY_NUMBER='1' AIRFLOW_CTX_DAG_RUN_ID='scheduled__2023-12-30T00:00:00+00:00'
[2024-01-02T17:55:18.158+0530] {taskinstance.py:1937} ERROR - Task failed with exception
Traceback (most recent call last):
  File "/home/rajabala/Desktop/projects/Airflow/airflow_env/lib/python3.9/site-packages/airflow/operators/python.py", line 192, in execute
    return_value = self.execute_callable()
  File "/home/rajabala/Desktop/projects/Airflow/airflow_env/lib/python3.9/site-packages/airflow/operators/python.py", line 209, in execute_callable
    return self.python_callable(*self.op_args, **self.op_kwargs)
  File "/home/rajabala/Desktop/projects/Airflow/dags/Cricbuzz_files/Load.py", line 9, in load_to_db
    file_name=url.split('/')[-1]
AttributeError: 'list' object has no attribute 'split'
[2024-01-02T17:55:18.161+0530] {taskinstance.py:1400} INFO - Marking task as FAILED. dag_id=Cricbuzz_ETL, task_id=load, execution_date=20231230T000000, start_date=20240102T122517, end_date=20240102T122518
[2024-01-02T17:55:18.175+0530] {standard_task_runner.py:104} ERROR - Failed to execute job 552 for task load ('list' object has no attribute 'split'; 25148)
[2024-01-02T17:55:18.196+0530] {local_task_job_runner.py:228} INFO - Task exited with return code 1
[2024-01-02T17:55:18.211+0530] {taskinstance.py:2778} INFO - 0 downstream tasks scheduled from follow-on schedule check
