[2024-01-01T14:20:56.780+0530] {taskinstance.py:1159} INFO - Dependencies all met for dep_context=non-requeueable deps ti=<TaskInstance: summa1.manual_trigger manual__2024-01-01T08:45:53.087736+00:00 [queued]>
[2024-01-01T14:20:56.784+0530] {taskinstance.py:1159} INFO - Dependencies all met for dep_context=requeueable deps ti=<TaskInstance: summa1.manual_trigger manual__2024-01-01T08:45:53.087736+00:00 [queued]>
[2024-01-01T14:20:56.784+0530] {taskinstance.py:1361} INFO - Starting attempt 2 of 2
[2024-01-01T14:20:56.792+0530] {taskinstance.py:1382} INFO - Executing <Task(TriggerDagRunOperator): manual_trigger> on 2024-01-01 08:45:53.087736+00:00
[2024-01-01T14:20:56.794+0530] {standard_task_runner.py:57} INFO - Started process 11706 to run task
[2024-01-01T14:20:56.796+0530] {standard_task_runner.py:84} INFO - Running: ['airflow', 'tasks', 'run', 'summa1', 'manual_trigger', 'manual__2024-01-01T08:45:53.087736+00:00', '--job-id', '504', '--raw', '--subdir', 'DAGS_FOLDER/summa.py', '--cfg-path', '/tmp/tmpcx9gv7pe']
[2024-01-01T14:20:56.797+0530] {standard_task_runner.py:85} INFO - Job 504: Subtask manual_trigger
[2024-01-01T14:20:56.816+0530] {task_command.py:416} INFO - Running <TaskInstance: summa1.manual_trigger manual__2024-01-01T08:45:53.087736+00:00 [running]> on host Iris
[2024-01-01T14:20:56.846+0530] {taskinstance.py:1662} INFO - Exporting env vars: AIRFLOW_CTX_DAG_OWNER='your_username' AIRFLOW_CTX_DAG_ID='summa1' AIRFLOW_CTX_TASK_ID='manual_trigger' AIRFLOW_CTX_EXECUTION_DATE='2024-01-01T08:45:53.087736+00:00' AIRFLOW_CTX_TRY_NUMBER='2' AIRFLOW_CTX_DAG_RUN_ID='manual__2024-01-01T08:45:53.087736+00:00'
[2024-01-01T14:20:56.885+0530] {taskinstance.py:1937} ERROR - Task failed with exception
Traceback (most recent call last):
  File "/home/rajabala/Desktop/projects/Airflow/airflow_env/lib/python3.9/site-packages/airflow/operators/trigger_dagrun.py", line 163, in execute
    dag_run = trigger_dag(
  File "/home/rajabala/Desktop/projects/Airflow/airflow_env/lib/python3.9/site-packages/airflow/api/common/trigger_dag.py", line 122, in trigger_dag
    triggers = _trigger_dag(
  File "/home/rajabala/Desktop/projects/Airflow/airflow_env/lib/python3.9/site-packages/airflow/api/common/trigger_dag.py", line 57, in _trigger_dag
    raise ValueError("The execution_date should be localized")
ValueError: The execution_date should be localized
[2024-01-01T14:20:56.888+0530] {taskinstance.py:1400} INFO - Marking task as FAILED. dag_id=summa1, task_id=manual_trigger, execution_date=20240101T084553, start_date=20240101T085056, end_date=20240101T085056
[2024-01-01T14:20:56.898+0530] {standard_task_runner.py:104} ERROR - Failed to execute job 504 for task manual_trigger (The execution_date should be localized; 11706)
[2024-01-01T14:20:56.928+0530] {local_task_job_runner.py:228} INFO - Task exited with return code 1
[2024-01-01T14:20:56.948+0530] {taskinstance.py:2778} INFO - 0 downstream tasks scheduled from follow-on schedule check
