[2023-12-31T21:09:08.144+0530] {taskinstance.py:1159} INFO - Dependencies all met for dep_context=non-requeueable deps ti=<TaskInstance: Cricbuzz_ETL3.load manual__2023-12-31T15:38:32.063539+00:00 [queued]>
[2023-12-31T21:09:08.149+0530] {taskinstance.py:1159} INFO - Dependencies all met for dep_context=requeueable deps ti=<TaskInstance: Cricbuzz_ETL3.load manual__2023-12-31T15:38:32.063539+00:00 [queued]>
[2023-12-31T21:09:08.149+0530] {taskinstance.py:1361} INFO - Starting attempt 1 of 1
[2023-12-31T21:09:08.162+0530] {taskinstance.py:1382} INFO - Executing <Task(PythonOperator): load> on 2023-12-31 15:38:32.063539+00:00
[2023-12-31T21:09:08.164+0530] {standard_task_runner.py:57} INFO - Started process 21556 to run task
[2023-12-31T21:09:08.166+0530] {standard_task_runner.py:84} INFO - Running: ['airflow', 'tasks', 'run', 'Cricbuzz_ETL3', 'load', 'manual__2023-12-31T15:38:32.063539+00:00', '--job-id', '478', '--raw', '--subdir', 'DAGS_FOLDER/my_dag.py', '--cfg-path', '/tmp/tmpt4mvqtr4']
[2023-12-31T21:09:08.167+0530] {standard_task_runner.py:85} INFO - Job 478: Subtask load
[2023-12-31T21:09:08.196+0530] {task_command.py:416} INFO - Running <TaskInstance: Cricbuzz_ETL3.load manual__2023-12-31T15:38:32.063539+00:00 [running]> on host Iris
[2023-12-31T21:09:08.241+0530] {taskinstance.py:1662} INFO - Exporting env vars: AIRFLOW_CTX_DAG_OWNER='airflow' AIRFLOW_CTX_DAG_ID='Cricbuzz_ETL3' AIRFLOW_CTX_TASK_ID='load' AIRFLOW_CTX_EXECUTION_DATE='2023-12-31T15:38:32.063539+00:00' AIRFLOW_CTX_TRY_NUMBER='1' AIRFLOW_CTX_DAG_RUN_ID='manual__2023-12-31T15:38:32.063539+00:00'
[2023-12-31T21:09:08.241+0530] {taskinstance.py:1937} ERROR - Task failed with exception
Traceback (most recent call last):
  File "/home/rajabala/Desktop/projects/Airflow/airflow_env/lib/python3.9/site-packages/airflow/operators/python.py", line 192, in execute
    return_value = self.execute_callable()
  File "/home/rajabala/Desktop/projects/Airflow/airflow_env/lib/python3.9/site-packages/airflow/operators/python.py", line 209, in execute_callable
    return self.python_callable(*self.op_args, **self.op_kwargs)
TypeError: load_to_db() takes 1 positional argument but 2 were given
[2023-12-31T21:09:08.244+0530] {taskinstance.py:1400} INFO - Marking task as FAILED. dag_id=Cricbuzz_ETL3, task_id=load, execution_date=20231231T153832, start_date=20231231T153908, end_date=20231231T153908
[2023-12-31T21:09:08.253+0530] {standard_task_runner.py:104} ERROR - Failed to execute job 478 for task load (load_to_db() takes 1 positional argument but 2 were given; 21556)
[2023-12-31T21:09:08.258+0530] {local_task_job_runner.py:228} INFO - Task exited with return code 1
[2023-12-31T21:09:08.266+0530] {taskinstance.py:2778} INFO - 0 downstream tasks scheduled from follow-on schedule check
