[2024-01-01T14:46:58.527+0530] {taskinstance.py:1159} INFO - Dependencies all met for dep_context=non-requeueable deps ti=<TaskInstance: summa1.manual_trigger scheduled__2023-12-31T00:00:00+00:00 [queued]>
[2024-01-01T14:46:58.532+0530] {taskinstance.py:1159} INFO - Dependencies all met for dep_context=requeueable deps ti=<TaskInstance: summa1.manual_trigger scheduled__2023-12-31T00:00:00+00:00 [queued]>
[2024-01-01T14:46:58.532+0530] {taskinstance.py:1361} INFO - Starting attempt 2 of 2
[2024-01-01T14:46:58.542+0530] {taskinstance.py:1382} INFO - Executing <Task(TriggerDagRunOperator): manual_trigger> on 2023-12-31 00:00:00+00:00
[2024-01-01T14:46:58.544+0530] {standard_task_runner.py:57} INFO - Started process 26922 to run task
[2024-01-01T14:46:58.547+0530] {standard_task_runner.py:84} INFO - Running: ['airflow', 'tasks', 'run', 'summa1', 'manual_trigger', 'scheduled__2023-12-31T00:00:00+00:00', '--job-id', '514', '--raw', '--subdir', 'DAGS_FOLDER/summa.py', '--cfg-path', '/tmp/tmpujjnxxfe']
[2024-01-01T14:46:58.547+0530] {standard_task_runner.py:85} INFO - Job 514: Subtask manual_trigger
[2024-01-01T14:46:58.571+0530] {task_command.py:416} INFO - Running <TaskInstance: summa1.manual_trigger scheduled__2023-12-31T00:00:00+00:00 [running]> on host Iris
[2024-01-01T14:46:58.613+0530] {taskinstance.py:1662} INFO - Exporting env vars: AIRFLOW_CTX_DAG_OWNER='your_username' AIRFLOW_CTX_DAG_ID='summa1' AIRFLOW_CTX_TASK_ID='manual_trigger' AIRFLOW_CTX_EXECUTION_DATE='2023-12-31T00:00:00+00:00' AIRFLOW_CTX_TRY_NUMBER='2' AIRFLOW_CTX_DAG_RUN_ID='scheduled__2023-12-31T00:00:00+00:00'
[2024-01-01T14:46:58.699+0530] {taskinstance.py:1937} ERROR - Task failed with exception
Traceback (most recent call last):
  File "/home/rajabala/Desktop/projects/Airflow/airflow_env/lib/python3.9/site-packages/airflow/operators/trigger_dagrun.py", line 186, in execute
    raise e
  File "/home/rajabala/Desktop/projects/Airflow/airflow_env/lib/python3.9/site-packages/airflow/operators/trigger_dagrun.py", line 163, in execute
    dag_run = trigger_dag(
  File "/home/rajabala/Desktop/projects/Airflow/airflow_env/lib/python3.9/site-packages/airflow/api/common/trigger_dag.py", line 122, in trigger_dag
    triggers = _trigger_dag(
  File "/home/rajabala/Desktop/projects/Airflow/airflow_env/lib/python3.9/site-packages/airflow/api/common/trigger_dag.py", line 78, in _trigger_dag
    raise DagRunAlreadyExists(dag_run=dag_run, execution_date=execution_date, run_id=run_id)
airflow.exceptions.DagRunAlreadyExists: A DAG Run already exists for DAG summa1 at 2023-12-31 00:00:00+00:00 with run id manual__2023-12-31T00:00:00+00:00
[2024-01-01T14:46:58.700+0530] {taskinstance.py:1400} INFO - Marking task as FAILED. dag_id=summa1, task_id=manual_trigger, execution_date=20231231T000000, start_date=20240101T091658, end_date=20240101T091658
[2024-01-01T14:46:58.708+0530] {standard_task_runner.py:104} ERROR - Failed to execute job 514 for task manual_trigger (A DAG Run already exists for DAG summa1 at 2023-12-31 00:00:00+00:00 with run id manual__2023-12-31T00:00:00+00:00; 26922)
[2024-01-01T14:46:58.719+0530] {local_task_job_runner.py:228} INFO - Task exited with return code 1
[2024-01-01T14:46:58.731+0530] {taskinstance.py:2778} INFO - 0 downstream tasks scheduled from follow-on schedule check
