[2024-01-02T17:03:01.804+0530] {taskinstance.py:1159} INFO - Dependencies all met for dep_context=non-requeueable deps ti=<TaskInstance: summa1.manual_trigger scheduled__2024-01-01T00:00:00+00:00 [queued]>
[2024-01-02T17:03:01.809+0530] {taskinstance.py:1159} INFO - Dependencies all met for dep_context=requeueable deps ti=<TaskInstance: summa1.manual_trigger scheduled__2024-01-01T00:00:00+00:00 [queued]>
[2024-01-02T17:03:01.809+0530] {taskinstance.py:1361} INFO - Starting attempt 1 of 2
[2024-01-02T17:03:01.821+0530] {taskinstance.py:1382} INFO - Executing <Task(TriggerDagRunOperator): manual_trigger> on 2024-01-01 00:00:00+00:00
[2024-01-02T17:03:01.823+0530] {standard_task_runner.py:57} INFO - Started process 4841 to run task
[2024-01-02T17:03:01.826+0530] {standard_task_runner.py:84} INFO - Running: ['airflow', 'tasks', 'run', 'summa1', 'manual_trigger', 'scheduled__2024-01-01T00:00:00+00:00', '--job-id', '517', '--raw', '--subdir', 'DAGS_FOLDER/summa.py', '--cfg-path', '/tmp/tmps49iwdbu']
[2024-01-02T17:03:01.827+0530] {standard_task_runner.py:85} INFO - Job 517: Subtask manual_trigger
[2024-01-02T17:03:01.864+0530] {task_command.py:416} INFO - Running <TaskInstance: summa1.manual_trigger scheduled__2024-01-01T00:00:00+00:00 [running]> on host Iris
[2024-01-02T17:03:01.925+0530] {taskinstance.py:1662} INFO - Exporting env vars: AIRFLOW_CTX_DAG_OWNER='your_username' AIRFLOW_CTX_DAG_ID='summa1' AIRFLOW_CTX_TASK_ID='manual_trigger' AIRFLOW_CTX_EXECUTION_DATE='2024-01-01T00:00:00+00:00' AIRFLOW_CTX_TRY_NUMBER='1' AIRFLOW_CTX_DAG_RUN_ID='scheduled__2024-01-01T00:00:00+00:00'
[2024-01-02T17:03:02.060+0530] {taskinstance.py:1937} ERROR - Task failed with exception
Traceback (most recent call last):
  File "/home/rajabala/Desktop/projects/Airflow/airflow_env/lib/python3.9/site-packages/airflow/operators/trigger_dagrun.py", line 186, in execute
    raise e
  File "/home/rajabala/Desktop/projects/Airflow/airflow_env/lib/python3.9/site-packages/airflow/operators/trigger_dagrun.py", line 163, in execute
    dag_run = trigger_dag(
  File "/home/rajabala/Desktop/projects/Airflow/airflow_env/lib/python3.9/site-packages/airflow/api/common/trigger_dag.py", line 122, in trigger_dag
    triggers = _trigger_dag(
  File "/home/rajabala/Desktop/projects/Airflow/airflow_env/lib/python3.9/site-packages/airflow/api/common/trigger_dag.py", line 78, in _trigger_dag
    raise DagRunAlreadyExists(dag_run=dag_run, execution_date=execution_date, run_id=run_id)
airflow.exceptions.DagRunAlreadyExists: A DAG Run already exists for DAG summa1 at 2023-12-31 00:00:00+00:00 with run id manual__2023-12-31T00:00:00+00:00
[2024-01-02T17:03:02.061+0530] {taskinstance.py:1400} INFO - Marking task as UP_FOR_RETRY. dag_id=summa1, task_id=manual_trigger, execution_date=20240101T000000, start_date=20240102T113301, end_date=20240102T113302
[2024-01-02T17:03:02.071+0530] {standard_task_runner.py:104} ERROR - Failed to execute job 517 for task manual_trigger (A DAG Run already exists for DAG summa1 at 2023-12-31 00:00:00+00:00 with run id manual__2023-12-31T00:00:00+00:00; 4841)
[2024-01-02T17:03:02.078+0530] {local_task_job_runner.py:228} INFO - Task exited with return code 1
[2024-01-02T17:03:02.094+0530] {taskinstance.py:2778} INFO - 0 downstream tasks scheduled from follow-on schedule check
