[2024-01-01T12:48:25.594+0530] {taskinstance.py:1159} INFO - Dependencies all met for dep_context=non-requeueable deps ti=<TaskInstance: Cricbuzz_ETL.Extract scheduled__2023-12-31T00:00:00+00:00 [queued]>
[2024-01-01T12:48:25.598+0530] {taskinstance.py:1159} INFO - Dependencies all met for dep_context=requeueable deps ti=<TaskInstance: Cricbuzz_ETL.Extract scheduled__2023-12-31T00:00:00+00:00 [queued]>
[2024-01-01T12:48:25.598+0530] {taskinstance.py:1361} INFO - Starting attempt 1 of 2
[2024-01-01T12:48:25.607+0530] {taskinstance.py:1382} INFO - Executing <Task(PythonOperator): Extract> on 2023-12-31 00:00:00+00:00
[2024-01-01T12:48:25.609+0530] {standard_task_runner.py:57} INFO - Started process 6933 to run task
[2024-01-01T12:48:25.610+0530] {standard_task_runner.py:84} INFO - Running: ['airflow', 'tasks', 'run', 'Cricbuzz_ETL', 'Extract', 'scheduled__2023-12-31T00:00:00+00:00', '--job-id', '501', '--raw', '--subdir', 'DAGS_FOLDER/Crickbuzz_dag.py', '--cfg-path', '/tmp/tmpa8bde69_']
[2024-01-01T12:48:25.611+0530] {standard_task_runner.py:85} INFO - Job 501: Subtask Extract
[2024-01-01T12:48:25.630+0530] {task_command.py:416} INFO - Running <TaskInstance: Cricbuzz_ETL.Extract scheduled__2023-12-31T00:00:00+00:00 [running]> on host Iris
[2024-01-01T12:48:25.663+0530] {taskinstance.py:1662} INFO - Exporting env vars: AIRFLOW_CTX_DAG_OWNER='airflow' AIRFLOW_CTX_DAG_ID='Cricbuzz_ETL' AIRFLOW_CTX_TASK_ID='Extract' AIRFLOW_CTX_EXECUTION_DATE='2023-12-31T00:00:00+00:00' AIRFLOW_CTX_TRY_NUMBER='1' AIRFLOW_CTX_DAG_RUN_ID='scheduled__2023-12-31T00:00:00+00:00'
[2024-01-01T12:48:25.667+0530] {logging_mixin.py:154} INFO - ['https://www.cricbuzz.com/cricket-full-commentary/66183/srh-vs-rr-4th-match-indian-premier-league-2023']
[2024-01-01T12:48:26.077+0530] {connectionpool.py:871} WARNING - Retrying (Retry(total=2, connect=None, read=None, redirect=None, status=None)) after connection broken by 'NewConnectionError('<urllib3.connection.HTTPConnection object at 0x7f36cd2932b0>: Failed to establish a new connection: [Errno 111] Connection refused')': /wd/hub/session
[2024-01-01T12:48:26.077+0530] {connectionpool.py:871} WARNING - Retrying (Retry(total=1, connect=None, read=None, redirect=None, status=None)) after connection broken by 'NewConnectionError('<urllib3.connection.HTTPConnection object at 0x7f36cd2935e0>: Failed to establish a new connection: [Errno 111] Connection refused')': /wd/hub/session
[2024-01-01T12:48:26.077+0530] {connectionpool.py:871} WARNING - Retrying (Retry(total=0, connect=None, read=None, redirect=None, status=None)) after connection broken by 'NewConnectionError('<urllib3.connection.HTTPConnection object at 0x7f36cd2939d0>: Failed to establish a new connection: [Errno 111] Connection refused')': /wd/hub/session
[2024-01-01T12:48:26.078+0530] {taskinstance.py:1937} ERROR - Task failed with exception
Traceback (most recent call last):
  File "/home/rajabala/Desktop/projects/Airflow/airflow_env/lib/python3.9/site-packages/urllib3/connection.py", line 203, in _new_conn
    sock = connection.create_connection(
  File "/home/rajabala/Desktop/projects/Airflow/airflow_env/lib/python3.9/site-packages/urllib3/util/connection.py", line 85, in create_connection
    raise err
  File "/home/rajabala/Desktop/projects/Airflow/airflow_env/lib/python3.9/site-packages/urllib3/util/connection.py", line 73, in create_connection
    sock.connect(sa)
ConnectionRefusedError: [Errno 111] Connection refused

The above exception was the direct cause of the following exception:

Traceback (most recent call last):
  File "/home/rajabala/Desktop/projects/Airflow/airflow_env/lib/python3.9/site-packages/urllib3/connectionpool.py", line 790, in urlopen
    response = self._make_request(
  File "/home/rajabala/Desktop/projects/Airflow/airflow_env/lib/python3.9/site-packages/urllib3/connectionpool.py", line 496, in _make_request
    conn.request(
  File "/home/rajabala/Desktop/projects/Airflow/airflow_env/lib/python3.9/site-packages/urllib3/connection.py", line 395, in request
    self.endheaders()
  File "/home/rajabala/anaconda3/lib/python3.9/http/client.py", line 1280, in endheaders
    self._send_output(message_body, encode_chunked=encode_chunked)
  File "/home/rajabala/anaconda3/lib/python3.9/http/client.py", line 1040, in _send_output
    self.send(msg)
  File "/home/rajabala/anaconda3/lib/python3.9/http/client.py", line 980, in send
    self.connect()
  File "/home/rajabala/Desktop/projects/Airflow/airflow_env/lib/python3.9/site-packages/urllib3/connection.py", line 243, in connect
    self.sock = self._new_conn()
  File "/home/rajabala/Desktop/projects/Airflow/airflow_env/lib/python3.9/site-packages/urllib3/connection.py", line 218, in _new_conn
    raise NewConnectionError(
urllib3.exceptions.NewConnectionError: <urllib3.connection.HTTPConnection object at 0x7f36cd293bb0>: Failed to establish a new connection: [Errno 111] Connection refused

The above exception was the direct cause of the following exception:

Traceback (most recent call last):
  File "/home/rajabala/Desktop/projects/Airflow/airflow_env/lib/python3.9/site-packages/airflow/operators/python.py", line 192, in execute
    return_value = self.execute_callable()
  File "/home/rajabala/Desktop/projects/Airflow/airflow_env/lib/python3.9/site-packages/airflow/operators/python.py", line 209, in execute_callable
    return self.python_callable(*self.op_args, **self.op_kwargs)
  File "/home/rajabala/Desktop/projects/Airflow/dags/Cricbuzz_files/Extract.py", line 32, in web_scrap
    driver = webdriver.Remote(command_executor=selenium_url, options=chrome_options)
  File "/home/rajabala/Desktop/projects/Airflow/airflow_env/lib/python3.9/site-packages/selenium/webdriver/remote/webdriver.py", line 209, in __init__
    self.start_session(capabilities)
  File "/home/rajabala/Desktop/projects/Airflow/airflow_env/lib/python3.9/site-packages/selenium/webdriver/remote/webdriver.py", line 293, in start_session
    response = self.execute(Command.NEW_SESSION, caps)["value"]
  File "/home/rajabala/Desktop/projects/Airflow/airflow_env/lib/python3.9/site-packages/selenium/webdriver/remote/webdriver.py", line 346, in execute
    response = self.command_executor.execute(driver_command, params)
  File "/home/rajabala/Desktop/projects/Airflow/airflow_env/lib/python3.9/site-packages/selenium/webdriver/remote/remote_connection.py", line 300, in execute
    return self._request(command_info[0], url, body=data)
  File "/home/rajabala/Desktop/projects/Airflow/airflow_env/lib/python3.9/site-packages/selenium/webdriver/remote/remote_connection.py", line 321, in _request
    response = self._conn.request(method, url, body=body, headers=headers)
  File "/home/rajabala/Desktop/projects/Airflow/airflow_env/lib/python3.9/site-packages/urllib3/_request_methods.py", line 118, in request
    return self.request_encode_body(
  File "/home/rajabala/Desktop/projects/Airflow/airflow_env/lib/python3.9/site-packages/urllib3/_request_methods.py", line 217, in request_encode_body
    return self.urlopen(method, url, **extra_kw)
  File "/home/rajabala/Desktop/projects/Airflow/airflow_env/lib/python3.9/site-packages/urllib3/poolmanager.py", line 444, in urlopen
    response = conn.urlopen(method, u.request_uri, **kw)
  File "/home/rajabala/Desktop/projects/Airflow/airflow_env/lib/python3.9/site-packages/urllib3/connectionpool.py", line 874, in urlopen
    return self.urlopen(
  File "/home/rajabala/Desktop/projects/Airflow/airflow_env/lib/python3.9/site-packages/urllib3/connectionpool.py", line 874, in urlopen
    return self.urlopen(
  File "/home/rajabala/Desktop/projects/Airflow/airflow_env/lib/python3.9/site-packages/urllib3/connectionpool.py", line 874, in urlopen
    return self.urlopen(
  File "/home/rajabala/Desktop/projects/Airflow/airflow_env/lib/python3.9/site-packages/urllib3/connectionpool.py", line 844, in urlopen
    retries = retries.increment(
  File "/home/rajabala/Desktop/projects/Airflow/airflow_env/lib/python3.9/site-packages/urllib3/util/retry.py", line 515, in increment
    raise MaxRetryError(_pool, url, reason) from reason  # type: ignore[arg-type]
urllib3.exceptions.MaxRetryError: HTTPConnectionPool(host='localhost', port=5555): Max retries exceeded with url: /wd/hub/session (Caused by NewConnectionError('<urllib3.connection.HTTPConnection object at 0x7f36cd293bb0>: Failed to establish a new connection: [Errno 111] Connection refused'))
[2024-01-01T12:48:26.084+0530] {taskinstance.py:1400} INFO - Marking task as UP_FOR_RETRY. dag_id=Cricbuzz_ETL, task_id=Extract, execution_date=20231231T000000, start_date=20240101T071825, end_date=20240101T071826
[2024-01-01T12:48:26.091+0530] {standard_task_runner.py:104} ERROR - Failed to execute job 501 for task Extract (HTTPConnectionPool(host='localhost', port=5555): Max retries exceeded with url: /wd/hub/session (Caused by NewConnectionError('<urllib3.connection.HTTPConnection object at 0x7f36cd293bb0>: Failed to establish a new connection: [Errno 111] Connection refused')); 6933)
[2024-01-01T12:48:26.103+0530] {local_task_job_runner.py:228} INFO - Task exited with return code 1
[2024-01-01T12:48:26.119+0530] {taskinstance.py:2778} INFO - 0 downstream tasks scheduled from follow-on schedule check
[2024-01-02T17:20:49.105+0530] {taskinstance.py:1159} INFO - Dependencies all met for dep_context=non-requeueable deps ti=<TaskInstance: Cricbuzz_ETL.Extract scheduled__2023-12-31T00:00:00+00:00 [queued]>
[2024-01-02T17:20:49.111+0530] {taskinstance.py:1159} INFO - Dependencies all met for dep_context=requeueable deps ti=<TaskInstance: Cricbuzz_ETL.Extract scheduled__2023-12-31T00:00:00+00:00 [queued]>
[2024-01-02T17:20:49.111+0530] {taskinstance.py:1361} INFO - Starting attempt 1 of 2
[2024-01-02T17:20:49.125+0530] {taskinstance.py:1382} INFO - Executing <Task(PythonOperator): Extract> on 2023-12-31 00:00:00+00:00
[2024-01-02T17:20:49.127+0530] {standard_task_runner.py:57} INFO - Started process 11764 to run task
[2024-01-02T17:20:49.130+0530] {standard_task_runner.py:84} INFO - Running: ['airflow', 'tasks', 'run', 'Cricbuzz_ETL', 'Extract', 'scheduled__2023-12-31T00:00:00+00:00', '--job-id', '539', '--raw', '--subdir', 'DAGS_FOLDER/Crickbuzz_dag.py', '--cfg-path', '/tmp/tmp66ad7z46']
[2024-01-02T17:20:49.132+0530] {standard_task_runner.py:85} INFO - Job 539: Subtask Extract
[2024-01-02T17:20:49.160+0530] {task_command.py:416} INFO - Running <TaskInstance: Cricbuzz_ETL.Extract scheduled__2023-12-31T00:00:00+00:00 [running]> on host Iris
[2024-01-02T17:20:49.207+0530] {taskinstance.py:1662} INFO - Exporting env vars: AIRFLOW_CTX_DAG_OWNER='airflow' AIRFLOW_CTX_DAG_ID='Cricbuzz_ETL' AIRFLOW_CTX_TASK_ID='Extract' AIRFLOW_CTX_EXECUTION_DATE='2023-12-31T00:00:00+00:00' AIRFLOW_CTX_TRY_NUMBER='1' AIRFLOW_CTX_DAG_RUN_ID='scheduled__2023-12-31T00:00:00+00:00'
[2024-01-02T17:20:49.208+0530] {logging_mixin.py:154} INFO - https://www.cricbuzz.com/cricket-full-commentary/75437/ind-vs-aus-5th-match-icc-cricket-world-cup-2023
[2024-01-02T17:20:49.208+0530] {logging_mixin.py:154} INFO - working
[2024-01-02T17:20:49.208+0530] {python.py:194} INFO - Done. Returned value was: None
[2024-01-02T17:20:49.211+0530] {taskinstance.py:1400} INFO - Marking task as SUCCESS. dag_id=Cricbuzz_ETL, task_id=Extract, execution_date=20231231T000000, start_date=20240102T115049, end_date=20240102T115049
[2024-01-02T17:20:49.262+0530] {local_task_job_runner.py:228} INFO - Task exited with return code 0
[2024-01-02T17:20:49.286+0530] {taskinstance.py:2778} INFO - 1 downstream tasks scheduled from follow-on schedule check
[2024-01-02T17:26:43.365+0530] {taskinstance.py:1159} INFO - Dependencies all met for dep_context=non-requeueable deps ti=<TaskInstance: Cricbuzz_ETL.Extract scheduled__2023-12-31T00:00:00+00:00 [queued]>
[2024-01-02T17:26:43.372+0530] {taskinstance.py:1159} INFO - Dependencies all met for dep_context=requeueable deps ti=<TaskInstance: Cricbuzz_ETL.Extract scheduled__2023-12-31T00:00:00+00:00 [queued]>
[2024-01-02T17:26:43.372+0530] {taskinstance.py:1361} INFO - Starting attempt 1 of 2
[2024-01-02T17:26:43.385+0530] {taskinstance.py:1382} INFO - Executing <Task(PythonOperator): Extract> on 2023-12-31 00:00:00+00:00
[2024-01-02T17:26:43.387+0530] {standard_task_runner.py:57} INFO - Started process 14765 to run task
[2024-01-02T17:26:43.391+0530] {standard_task_runner.py:84} INFO - Running: ['airflow', 'tasks', 'run', 'Cricbuzz_ETL', 'Extract', 'scheduled__2023-12-31T00:00:00+00:00', '--job-id', '543', '--raw', '--subdir', 'DAGS_FOLDER/Crickbuzz_dag.py', '--cfg-path', '/tmp/tmpf9yjrcg7']
[2024-01-02T17:26:43.392+0530] {standard_task_runner.py:85} INFO - Job 543: Subtask Extract
[2024-01-02T17:26:43.420+0530] {task_command.py:416} INFO - Running <TaskInstance: Cricbuzz_ETL.Extract scheduled__2023-12-31T00:00:00+00:00 [running]> on host Iris
[2024-01-02T17:26:43.468+0530] {taskinstance.py:1662} INFO - Exporting env vars: AIRFLOW_CTX_DAG_OWNER='airflow' AIRFLOW_CTX_DAG_ID='Cricbuzz_ETL' AIRFLOW_CTX_TASK_ID='Extract' AIRFLOW_CTX_EXECUTION_DATE='2023-12-31T00:00:00+00:00' AIRFLOW_CTX_TRY_NUMBER='1' AIRFLOW_CTX_DAG_RUN_ID='scheduled__2023-12-31T00:00:00+00:00'
[2024-01-02T17:26:43.469+0530] {logging_mixin.py:154} INFO - https://www.cricbuzz.com/cricket-full-commentary/75437/ind-vs-aus-5th-match-icc-cricket-world-cup-2023
[2024-01-02T17:26:43.469+0530] {logging_mixin.py:154} INFO - working
[2024-01-02T17:26:43.469+0530] {python.py:194} INFO - Done. Returned value was: None
[2024-01-02T17:26:43.473+0530] {taskinstance.py:1400} INFO - Marking task as SUCCESS. dag_id=Cricbuzz_ETL, task_id=Extract, execution_date=20231231T000000, start_date=20240102T115643, end_date=20240102T115643
[2024-01-02T17:26:43.523+0530] {local_task_job_runner.py:228} INFO - Task exited with return code 0
[2024-01-02T17:26:43.548+0530] {taskinstance.py:2778} INFO - 1 downstream tasks scheduled from follow-on schedule check
