[2023-12-31T22:01:51.720+0530] {taskinstance.py:1159} INFO - Dependencies all met for dep_context=non-requeueable deps ti=<TaskInstance: trigger.bash manual__2023-12-31T16:31:44.318886+00:00 [queued]>
[2023-12-31T22:01:51.725+0530] {taskinstance.py:1159} INFO - Dependencies all met for dep_context=requeueable deps ti=<TaskInstance: trigger.bash manual__2023-12-31T16:31:44.318886+00:00 [queued]>
[2023-12-31T22:01:51.726+0530] {taskinstance.py:1361} INFO - Starting attempt 1 of 2
[2023-12-31T22:01:51.741+0530] {taskinstance.py:1382} INFO - Executing <Task(BashOperator): bash> on 2023-12-31 16:31:44.318886+00:00
[2023-12-31T22:01:51.744+0530] {standard_task_runner.py:57} INFO - Started process 40190 to run task
[2023-12-31T22:01:51.747+0530] {standard_task_runner.py:84} INFO - Running: ['airflow', 'tasks', 'run', 'trigger', 'bash', 'manual__2023-12-31T16:31:44.318886+00:00', '--job-id', '527', '--raw', '--subdir', 'DAGS_FOLDER/summa.py', '--cfg-path', '/tmp/tmp_2tyutn8']
[2023-12-31T22:01:51.748+0530] {standard_task_runner.py:85} INFO - Job 527: Subtask bash
[2023-12-31T22:01:51.783+0530] {task_command.py:416} INFO - Running <TaskInstance: trigger.bash manual__2023-12-31T16:31:44.318886+00:00 [running]> on host Iris
[2023-12-31T22:01:51.837+0530] {taskinstance.py:1662} INFO - Exporting env vars: AIRFLOW_CTX_DAG_OWNER='airflow' AIRFLOW_CTX_DAG_ID='trigger' AIRFLOW_CTX_TASK_ID='bash' AIRFLOW_CTX_EXECUTION_DATE='2023-12-31T16:31:44.318886+00:00' AIRFLOW_CTX_TRY_NUMBER='1' AIRFLOW_CTX_DAG_RUN_ID='manual__2023-12-31T16:31:44.318886+00:00'
[2023-12-31T22:01:51.838+0530] {subprocess.py:63} INFO - Tmp dir root location: /tmp
[2023-12-31T22:01:51.839+0530] {subprocess.py:75} INFO - Running command: ['/usr/bin/bash', '-c', "'echo' execution_date =2023-12-31 link = <TaskInstance: trigger.bash manual__2023-12-31T16:31:44.318886+00:00 [running]>"]
[2023-12-31T22:01:51.845+0530] {subprocess.py:86} INFO - Output:
[2023-12-31T22:01:51.846+0530] {subprocess.py:93} INFO - /usr/bin/bash: -c: line 1: syntax error near unexpected token `newline'
[2023-12-31T22:01:51.846+0530] {subprocess.py:93} INFO - /usr/bin/bash: -c: line 1: `'echo' execution_date =2023-12-31 link = <TaskInstance: trigger.bash manual__2023-12-31T16:31:44.318886+00:00 [running]>'
[2023-12-31T22:01:51.847+0530] {subprocess.py:97} INFO - Command exited with return code 2
[2023-12-31T22:01:51.854+0530] {taskinstance.py:1937} ERROR - Task failed with exception
Traceback (most recent call last):
  File "/home/rajabala/Desktop/projects/Airflow/airflow_env/lib/python3.9/site-packages/airflow/operators/bash.py", line 210, in execute
    raise AirflowException(
airflow.exceptions.AirflowException: Bash command failed. The command returned a non-zero exit code 2.
[2023-12-31T22:01:51.856+0530] {taskinstance.py:1400} INFO - Marking task as UP_FOR_RETRY. dag_id=trigger, task_id=bash, execution_date=20231231T163144, start_date=20231231T163151, end_date=20231231T163151
[2023-12-31T22:01:51.866+0530] {standard_task_runner.py:104} ERROR - Failed to execute job 527 for task bash (Bash command failed. The command returned a non-zero exit code 2.; 40190)
[2023-12-31T22:01:51.878+0530] {local_task_job_runner.py:228} INFO - Task exited with return code 1
[2023-12-31T22:01:51.890+0530] {taskinstance.py:2778} INFO - 0 downstream tasks scheduled from follow-on schedule check
