[2023-12-31T21:03:59.335+0530] {taskinstance.py:1159} INFO - Dependencies all met for dep_context=non-requeueable deps ti=<TaskInstance: Cricbuzz_ETL1.Extract manual__2023-12-31T15:33:30.670941+00:00 [queued]>
[2023-12-31T21:03:59.349+0530] {taskinstance.py:1159} INFO - Dependencies all met for dep_context=requeueable deps ti=<TaskInstance: Cricbuzz_ETL1.Extract manual__2023-12-31T15:33:30.670941+00:00 [queued]>
[2023-12-31T21:03:59.350+0530] {taskinstance.py:1361} INFO - Starting attempt 2 of 2
[2023-12-31T21:03:59.371+0530] {taskinstance.py:1382} INFO - Executing <Task(PythonOperator): Extract> on 2023-12-31 15:33:30.670941+00:00
[2023-12-31T21:03:59.373+0530] {standard_task_runner.py:57} INFO - Started process 18131 to run task
[2023-12-31T21:03:59.376+0530] {standard_task_runner.py:84} INFO - Running: ['airflow', 'tasks', 'run', 'Cricbuzz_ETL1', 'Extract', 'manual__2023-12-31T15:33:30.670941+00:00', '--job-id', '444', '--raw', '--subdir', 'DAGS_FOLDER/summa.py', '--cfg-path', '/tmp/tmpfz99e0_t']
[2023-12-31T21:03:59.377+0530] {standard_task_runner.py:85} INFO - Job 444: Subtask Extract
[2023-12-31T21:03:59.413+0530] {task_command.py:416} INFO - Running <TaskInstance: Cricbuzz_ETL1.Extract manual__2023-12-31T15:33:30.670941+00:00 [running]> on host Iris
[2023-12-31T21:03:59.460+0530] {taskinstance.py:1662} INFO - Exporting env vars: AIRFLOW_CTX_DAG_OWNER='airflow' AIRFLOW_CTX_DAG_ID='Cricbuzz_ETL1' AIRFLOW_CTX_TASK_ID='Extract' AIRFLOW_CTX_EXECUTION_DATE='2023-12-31T15:33:30.670941+00:00' AIRFLOW_CTX_TRY_NUMBER='2' AIRFLOW_CTX_DAG_RUN_ID='manual__2023-12-31T15:33:30.670941+00:00'
[2023-12-31T21:03:59.461+0530] {taskinstance.py:1937} ERROR - Task failed with exception
Traceback (most recent call last):
  File "/home/rajabala/Desktop/projects/Airflow/airflow_env/lib/python3.9/site-packages/airflow/operators/python.py", line 192, in execute
    return_value = self.execute_callable()
  File "/home/rajabala/Desktop/projects/Airflow/airflow_env/lib/python3.9/site-packages/airflow/operators/python.py", line 209, in execute_callable
    return self.python_callable(*self.op_args, **self.op_kwargs)
TypeError: web_scrap() takes 1 positional argument but 2 were given
[2023-12-31T21:03:59.465+0530] {taskinstance.py:1400} INFO - Marking task as FAILED. dag_id=Cricbuzz_ETL1, task_id=Extract, execution_date=20231231T153330, start_date=20231231T153359, end_date=20231231T153359
[2023-12-31T21:03:59.480+0530] {standard_task_runner.py:104} ERROR - Failed to execute job 444 for task Extract (web_scrap() takes 1 positional argument but 2 were given; 18131)
[2023-12-31T21:03:59.508+0530] {local_task_job_runner.py:228} INFO - Task exited with return code 1
[2023-12-31T21:03:59.528+0530] {taskinstance.py:2778} INFO - 0 downstream tasks scheduled from follow-on schedule check
